Workbook

Sheet Calendario
A1: Fecha | B1: Dia | C1: SUSANNA | D1: ZUA | E1: PEPE | F1: ANTO | G1: ELIAS | H1: CRIS
A2: JULIO 2026
A3: 46204 | B3: Mie
A4: 46205 | B4: Jue
A5: 46206 | B5: Vie
A6: 46207 | B6: Sab
A7: 46208 | B7: Dom
A8: 46209 | B8: Lun
A9: 46210 | B9: Mar
A10: 46211 | B10: Mie
A11: 46212 | B11: Jue
A12: 46213 | B12: Vie
A13: 46214 | B13: Sab
A14: 46215 | B14: Dom
... A33: 46234 | B33: Vie
A34: AGOSTO 2026
A35: 46235 | B35: Sab
A36: 46236 | B36: Dom
A37: 46237 | B37: Lun
A38: 46238 | B38: Mar
A39: 46239 | B39: Mie
A40: 46240 | B40: Jue
A41: 46241 | B41: Vie
A42: 46242 | B42: Sab
A43: 46243 | B43: Dom
A44: 46244 | B44: Lun
A45: 46245 | B45: Mar
A46: 46246 | B46: Mie
... A65: 46265 | B65: Lun
A68: LEYENDA
B69: TM -> Trabajar manana (~08-15)
B70: TT -> Trabajar tarde (~15-21)
B71: TN -> Trabajar noche (~21-08)
B72: FV -> Fuera (puedo volver)
B73: FN -> Fuera (NO volver)
B74: OC -> Ocupado
B75: RE -> Recuperaciones
B76: OT -> Otros
B77: CL -> Clases
B78: (vacio = disponible)

Sheet Resumen
A1: PANEL DE DISPONIBILIDAD — JULIO & AGOSTO 2026
B2: TOTAL DIAS | C2: 62 | E2: TODOS LIBRES | F2: =COUNTIF(J6:J67,"SI") | H2: MAX 1 OCUPADO | I2: =COUNTIF(K6:K67,"SI") | K2: MAX 2 OCUPADOS | L2: =COUNTIF(L6:L67,"SI") | N2: MAX 3 OCUPADOS | O2: =COUNTIF(M6:M67,"SI")
A4: Fecha | B4: Dia | C4: Libres | D4: TM | E4: TT | F4: TN | G4: FV | H4: FN | I4: Ocupados (TM+TT+TN) | J4: Todos libres | K4: Todos -1 | L4: Todos -2 | M4: Todos -3 | N4: Todos FN | O4: % Disponible
J5: Umbrales: minimo de personas libres
A6: 46204 | B6: Mie | C6: =COUNTIF(Calendario!C3:H3,"") | D6: =COUNTIF(Calendario!C3:H3,"TM") | E6: =COUNTIF(Calendario!C3:H3,"TT") | F6: =COUNTIF(Calendario!C3:H3,"TN") | G6: =COUNTIF(Calendario!C3:H3,"FV") | H6: =COUNTIF(Calendario!C3:H3,"FN") | I6: =D6+E6+F6 | J6: =IF(C6>=6,"SI","") | K6: =IF(C6>=5,"SI","") | L6: =IF(C6>=4,"SI","") | M6: =IF(C6>=3,"SI","") | N6: =IF(H6=6,"SI","") | O6: =C6/6
A7: 46205 | B7: Jue | C7: =COUNTIF(Calendario!C4:H4,"") | D7: =COUNTIF(Calendario!C4:H4,"TM") | E7: =COUNTIF(Calendario!C4:H4,"TT") | F7: =COUNTIF(Calendario!C4:H4,"TN") | G7: =COUNTIF(Calendario!C4:H4,"FV") | H7: =COUNTIF(Calendario!C4:H4,"FN") | I7: =D7+E7+F7 | J7: =IF(C7>=6,"SI","") | K7: =IF(C7>=5,"SI","") | L7: =IF(C7>=4,"SI","") | M7: =IF(C7>=3,"SI","") | N7: =IF(H7=6,"SI","") | O7: =C7/6
A8: 46206 | B8: Vie | C8: =COUNTIF(Calendario!C5:H5,"") | D8: =COUNTIF(Calendario!C5:H5,"TM") | E8: =COUNTIF(Calendario!C5:H5,"TT") | F8: =COUNTIF(Calendario!C5:H5,"TN") | G8: =COUNTIF(Calendario!C5:H5,"FV") | H8: =COUNTIF(Calendario!C5:H5,"FN") | I8: =D8+E8+F8 | J8: =IF(C8>=6,"SI","") | K8: =IF(C8>=5,"SI","") | L8: =IF(C8>=4,"SI","") | M8: =IF(C8>=3,"SI","") | N8: =IF(H8=6,"SI","") | O8: =C8/6
A9: 46207 | B9: Sab | C9: =COUNTIF(Calendario!C6:H6,"") | D9: =COUNTIF(Calendario!C6:H6,"TM") | E9: =COUNTIF(Calendario!C6:H6,"TT") | F9: =COUNTIF(Calendario!C6:H6,"TN") | G9: =COUNTIF(Calendario!C6:H6,"FV") | H9: =COUNTIF(Calendario!C6:H6,"FN") | I9: =D9+E9+F9 | J9: =IF(C9>=6,"SI","") | K9: =IF(C9>=5,"SI","") | L9: =IF(C9>=4,"SI","") | M9: =IF(C9>=3,"SI","") | N9: =IF(H9=6,"SI","") | O9: =C9/6
A10: 46208 | B10: Dom | C10: =COUNTIF(Calendario!C7:H7,"") | D10: =COUNTIF(Calendario!C7:H7,"TM") | E10: =COUNTIF(Calendario!C7:H7,"TT") | F10: =COUNTIF(Calendario!C7:H7,"TN") | G10: =COUNTIF(Calendario!C7:H7,"FV") | H10: =COUNTIF(Calendario!C7:H7,"FN") | I10: =D10+E10+F10 | J10: =IF(C10>=6,"SI","") | K10: =IF(C10>=5,"SI","") | L10: =IF(C10>=4,"SI","") | M10: =IF(C10>=3,"SI","") | N10: =IF(H10=6,"SI","") | O10: =C10/6
A11: 46209 | B11: Lun | C11: =COUNTIF(Calendario!C8:H8,"") | D11: =COUNTIF(Calendario!C8:H8,"TM") | E11: =COUNTIF(Calendario!C8:H8,"TT") | F11: =COUNTIF(Calendario!C8:H8,"TN") | G11: =COUNTIF(Calendario!C8:H8,"FV") | H11: =COUNTIF(Calendario!C8:H8,"FN") | I11: =D11+E11+F11 | J11: =IF(C11>=6,"SI","") | K11: =IF(C11>=5,"SI","") | L11: =IF(C11>=4,"SI","") | M11: =IF(C11>=3,"SI","") | N11: =IF(H11=6,"SI","") | O11: =C11/6
A12: 46210 | B12: Mar | C12: =COUNTIF(Calendario!C9:H9,"") | D12: =COUNTIF(Calendario!C9:H9,"TM") | E12: =COUNTIF(Calendario!C9:H9,"TT") | F12: =COUNTIF(Calendario!C9:H9,"TN") | G12: =COUNTIF(Calendario!C9:H9,"FV") | H12: =COUNTIF(Calendario!C9:H9,"FN") | I12: =D12+E12+F12 | J12: =IF(C12>=6,"SI","") | K12: =IF(C12>=5,"SI","") | L12: =IF(C12>=4,"SI","") | M12: =IF(C12>=3,"SI","") | N12: =IF(H12=6,"SI","") | O12: =C12/6
A13: 46211 | B13: Mie | C13: =COUNTIF(Calendario!C10:H10,"") | D13: =COUNTIF(Calendario!C10:H10,"TM") | E13: =COUNTIF(Calendario!C10:H10,"TT") | F13: =COUNTIF(Calendario!C10:H10,"TN") | G13: =COUNTIF(Calendario!C10:H10,"FV") | H13: =COUNTIF(Calendario!C10:H10,"FN") | I13: =D13+E13+F13 | J13: =IF(C13>=6,"SI","") | K13: =IF(C13>=5,"SI","") | L13: =IF(C13>=4,"SI","") | M13: =IF(C13>=3,"SI","") | N13: =IF(H13=6,"SI","") | O13: =C13/6
A14: 46212 | B14: Jue | C14: =COUNTIF(Calendario!C11:H11,"") | D14: =COUNTIF(Calendario!C11:H11,"TM") | E14: =COUNTIF(Calendario!C11:H11,"TT") | F14: =COUNTIF(Calendario!C11:H11,"TN") | G14: =COUNTIF(Calendario!C11:H11,"FV") | H14: =COUNTIF(Calendario!C11:H11,"FN") | I14: =D14+E14+F14 | J14: =IF(C14>=6,"SI","") | K14: =IF(C14>=5,"SI","") | L14: =IF(C14>=4,"SI","") | M14: =IF(C14>=3,"SI","") | N14: =IF(H14=6,"SI","") | O14: =C14/6
A15: 46213 | B15: Vie | C15: =COUNTIF(Calendario!C12:H12,"") | D15: =COUNTIF(Calendario!C12:H12,"TM") | E15: =COUNTIF(Calendario!C12:H12,"TT") | F15: =COUNTIF(Calendario!C12:H12,"TN") | G15: =COUNTIF(Calendario!C12:H12,"FV") | H15: =COUNTIF(Calendario!C12:H12,"FN") | I15: =D15+E15+F15 | J15: =IF(C15>=6,"SI","") | K15: =IF(C15>=5,"SI","") | L15: =IF(C15>=4,"SI","") | M15: =IF(C15>=3,"SI","") | N15: =IF(H15=6,"SI","") | O15: =C15/6
A16: 46214 | B16: Sab | C16: =COUNTIF(Calendario!C13:H13,"") | D16: =COUNTIF(Calendario!C13:H13,"TM") | E16: =COUNTIF(Calendario!C13:H13,"TT") | F16: =COUNTIF(Calendario!C13:H13,"TN") | G16: =COUNTIF(Calendario!C13:H13,"FV") | H16: =COUNTIF(Calendario!C13:H13,"FN") | I16: =D16+E16+F16 | J16: =IF(C16>=6,"SI","") | K16: =IF(C16>=5,"SI","") | L16: =IF(C16>=4,"SI","") | M16: =IF(C16>=3,"SI","") | N16: =IF(H16=6,"SI","") | O16: =C16/6
A17: 46215 | B17: Dom | C17: =COUNTIF(Calendario!C14:H14,"") | D17: =COUNTIF(Calendario!C14:H14,"TM") | E17: =COUNTIF(Calendario!C14:H14,"TT") | F17: =COUNTIF(Calendario!C14:H14,"TN") | G17: =COUNTIF(Calendario!C14:H14,"FV") | H17: =COUNTIF(Calendario!C14:H14,"FN") | I17: =D17+E17+F17 | J17: =IF(C17>=6,"SI","") | K17: =IF(C17>=5,"SI","") | L17: =IF(C17>=4,"SI","") | M17: =IF(C17>=3,"SI","") | N17: =IF(H17=6,"SI","") | O17: =C17/6
... A36: 46234 | B36: Vie | C36: =COUNTIF(Calendario!C33:H33,"") | D36: =COUNTIF(Calendario!C33:H33,"TM") | E36: =COUNTIF(Calendario!C33:H33,"TT") | F36: =COUNTIF(Calendario!C33:H33,"TN") | G36: =COUNTIF(Calendario!C33:H33,"FV") | H36: =COUNTIF(Calendario!C33:H33,"FN") | I36: =D36+E36+F36 | J36: =IF(C36>=6,"SI","") | K36: =IF(C36>=5,"SI","") | L36: =IF(C36>=4,"SI","") | M36: =IF(C36>=3,"SI","") | N36: =IF(H36=6,"SI","") | O36: =C36/6
A37: 46235 | B37: Sab | C37: =COUNTIF(Calendario!C35:H35,"") | D37: =COUNTIF(Calendario!C35:H35,"TM") | E37: =COUNTIF(Calendario!C35:H35,"TT") | F37: =COUNTIF(Calendario!C35:H35,"TN") | G37: =COUNTIF(Calendario!C35:H35,"FV") | H37: =COUNTIF(Calendario!C35:H35,"FN") | I37: =D37+E37+F37 | J37: =IF(C37>=6,"SI","") | K37: =IF(C37>=5,"SI","") | L37: =IF(C37>=4,"SI","") | M37: =IF(C37>=3,"SI","") | N37: =IF(H37=6,"SI","") | O37: =C37/6
A38: 46236 | B38: Dom | C38: =COUNTIF(Calendario!C36:H36,"") | D38: =COUNTIF(Calendario!C36:H36,"TM") | E38: =COUNTIF(Calendario!C36:H36,"TT") | F38: =COUNTIF(Calendario!C36:H36,"TN") | G38: =COUNTIF(Calendario!C36:H36,"FV") | H38: =COUNTIF(Calendario!C36:H36,"FN") | I38: =D38+E38+F38 | J38: =IF(C38>=6,"SI","") | K38: =IF(C38>=5,"SI","") | L38: =IF(C38>=4,"SI","") | M38: =IF(C38>=3,"SI","") | N38: =IF(H38=6,"SI","") | O38: =C38/6
A39: 46237 | B39: Lun | C39: =COUNTIF(Calendario!C37:H37,"") | D39: =COUNTIF(Calendario!C37:H37,"TM") | E39: =COUNTIF(Calendario!C37:H37,"TT") | F39: =COUNTIF(Calendario!C37:H37,"TN") | G39: =COUNTIF(Calendario!C37:H37,"FV") | H39: =COUNTIF(Calendario!C37:H37,"FN") | I39: =D39+E39+F39 | J39: =IF(C39>=6,"SI","") | K39: =IF(C39>=5,"SI","") | L39: =IF(C39>=4,"SI","") | M39: =IF(C39>=3,"SI","") | N39: =IF(H39=6,"SI","") | O39: =C39/6
A40: 46238 | B40: Mar | C40: =COUNTIF(Calendario!C38:H38,"") | D40: =COUNTIF(Calendario!C38:H38,"TM") | E40: =COUNTIF(Calendario!C38:H38,"TT") | F40: =COUNTIF(Calendario!C38:H38,"TN") | G40: =COUNTIF(Calendario!C38:H38,"FV") | H40: =COUNTIF(Calendario!C38:H38,"FN") | I40: =D40+E40+F40 | J40: =IF(C40>=6,"SI","") | K40: =IF(C40>=5,"SI","") | L40: =IF(C40>=4,"SI","") | M40: =IF(C40>=3,"SI","") | N40: =IF(H40=6,"SI","") | O40: =C40/6
A41: 46239 | B41: Mie | C41: =COUNTIF(Calendario!C39:H39,"") | D41: =COUNTIF(Calendario!C39:H39,"TM") | E41: =COUNTIF(Calendario!C39:H39,"TT") | F41: =COUNTIF(Calendario!C39:H39,"TN") | G41: =COUNTIF(Calendario!C39:H39,"FV") | H41: =COUNTIF(Calendario!C39:H39,"FN") | I41: =D41+E41+F41 | J41: =IF(C41>=6,"SI","") | K41: =IF(C41>=5,"SI","") | L41: =IF(C41>=4,"SI","") | M41: =IF(C41>=3,"SI","") | N41: =IF(H41=6,"SI","") | O41: =C41/6
A42: 46240 | B42: Jue | C42: =COUNTIF(Calendario!C40:H40,"") | D42: =COUNTIF(Calendario!C40:H40,"TM") | E42: =COUNTIF(Calendario!C40:H40,"TT") | F42: =COUNTIF(Calendario!C40:H40,"TN") | G42: =COUNTIF(Calendario!C40:H40,"FV") | H42: =COUNTIF(Calendario!C40:H40,"FN") | I42: =D42+E42+F42 | J42: =IF(C42>=6,"SI","") | K42: =IF(C42>=5,"SI","") | L42: =IF(C42>=4,"SI","") | M42: =IF(C42>=3,"SI","") | N42: =IF(H42=6,"SI","") | O42: =C42/6
A43: 46241 | B43: Vie | C43: =COUNTIF(Calendario!C41:H41,"") | D43: =COUNTIF(Calendario!C41:H41,"TM") | E43: =COUNTIF(Calendario!C41:H41,"TT") | F43: =COUNTIF(Calendario!C41:H41,"TN") | G43: =COUNTIF(Calendario!C41:H41,"FV") | H43: =COUNTIF(Calendario!C41:H41,"FN") | I43: =D43+E43+F43 | J43: =IF(C43>=6,"SI","") | K43: =IF(C43>=5,"SI","") | L43: =IF(C43>=4,"SI","") | M43: =IF(C43>=3,"SI","") | N43: =IF(H43=6,"SI","") | O43: =C43/6
A44: 46242 | B44: Sab | C44: =COUNTIF(Calendario!C42:H42,"") | D44: =COUNTIF(Calendario!C42:H42,"TM") | E44: =COUNTIF(Calendario!C42:H42,"TT") | F44: =COUNTIF(Calendario!C42:H42,"TN") | G44: =COUNTIF(Calendario!C42:H42,"FV") | H44: =COUNTIF(Calendario!C42:H42,"FN") | I44: =D44+E44+F44 | J44: =IF(C44>=6,"SI","") | K44: =IF(C44>=5,"SI","") | L44: =IF(C44>=4,"SI","") | M44: =IF(C44>=3,"SI","") | N44: =IF(H44=6,"SI","") | O44: =C44/6
A45: 46243 | B45: Dom | C45: =COUNTIF(Calendario!C43:H43,"") | D45: =COUNTIF(Calendario!C43:H43,"TM") | E45: =COUNTIF(Calendario!C43:H43,"TT") | F45: =COUNTIF(Calendario!C43:H43,"TN") | G45: =COUNTIF(Calendario!C43:H43,"FV") | H45: =COUNTIF(Calendario!C43:H43,"FN") | I45: =D45+E45+F45 | J45: =IF(C45>=6,"SI","") | K45: =IF(C45>=5,"SI","") | L45: =IF(C45>=4,"SI","") | M45: =IF(C45>=3,"SI","") | N45: =IF(H45=6,"SI","") | O45: =C45/6
A46: 46244 | B46: Lun | C46: =COUNTIF(Calendario!C44:H44,"") | D46: =COUNTIF(Calendario!C44:H44,"TM") | E46: =COUNTIF(Calendario!C44:H44,"TT") | F46: =COUNTIF(Calendario!C44:H44,"TN") | G46: =COUNTIF(Calendario!C44:H44,"FV") | H46: =COUNTIF(Calendario!C44:H44,"FN") | I46: =D46+E46+F46 | J46: =IF(C46>=6,"SI","") | K46: =IF(C46>=5,"SI","") | L46: =IF(C46>=4,"SI","") | M46: =IF(C46>=3,"SI","") | N46: =IF(H46=6,"SI","") | O46: =C46/6
A47: 46245 | B47: Mar | C47: =COUNTIF(Calendario!C45:H45,"") | D47: =COUNTIF(Calendario!C45:H45,"TM") | E47: =COUNTIF(Calendario!C45:H45,"TT") | F47: =COUNTIF(Calendario!C45:H45,"TN") | G47: =COUNTIF(Calendario!C45:H45,"FV") | H47: =COUNTIF(Calendario!C45:H45,"FN") | I47: =D47+E47+F47 | J47: =IF(C47>=6,"SI","") | K47: =IF(C47>=5,"SI","") | L47: =IF(C47>=4,"SI","") | M47: =IF(C47>=3,"SI","") | N47: =IF(H47=6,"SI","") | O47: =C47/6
A48: 46246 | B48: Mie | C48: =COUNTIF(Calendario!C46:H46,"") | D48: =COUNTIF(Calendario!C46:H46,"TM") | E48: =COUNTIF(Calendario!C46:H46,"TT") | F48: =COUNTIF(Calendario!C46:H46,"TN") | G48: =COUNTIF(Calendario!C46:H46,"FV") | H48: =COUNTIF(Calendario!C46:H46,"FN") | I48: =D48+E48+F48 | J48: =IF(C48>=6,"SI","") | K48: =IF(C48>=5,"SI","") | L48: =IF(C48>=4,"SI","") | M48: =IF(C48>=3,"SI","") | N48: =IF(H48=6,"SI","") | O48: =C48/6
... A67: 46265 | B67: Lun | C67: =COUNTIF(Calendario!C65:H65,"") | D67: =COUNTIF(Calendario!C65:H65,"TM") | E67: =COUNTIF(Calendario!C65:H65,"TT") | F67: =COUNTIF(Calendario!C65:H65,"TN") | G67: =COUNTIF(Calendario!C65:H65,"FV") | H67: =COUNTIF(Calendario!C65:H65,"FN") | I67: =D67+E67+F67 | J67: =IF(C67>=6,"SI","") | K67: =IF(C67>=5,"SI","") | L67: =IF(C67>=4,"SI","") | M67: =IF(C67>=3,"SI","") | N67: =IF(H67=6,"SI","") | O67: =C67/6
A68: TOTALES | C68: =SUM(C6:C67) | D68: =SUM(D6:D67) | E68: =SUM(E6:E67) | F68: =SUM(F6:F67) | G68: =SUM(G6:G67) | H68: =SUM(H6:H67) | I68: =SUM(I6:I67) | J68: =SUM(J6:J67) | ... N68: =SUM(N6:N67) | O68: =AVERAGE(O6:O67)

Sheet Julio
A1: JULIO 2026 — Quien puede cada dia
A2: 1 | B2: 46204 | C2: Mie | D2: =TEXTJOIN(", ";TRUE,IF(Calendario!C3="","SUSANNA",""), IF(Calendario!D3="","ZUA",""), IF(Calendario!E3="","PEPE",""), IF(Calendario!F3="","ANTO",""), IF(Calendario!G3="","ELIAS",""), IF(Calendario!H3="","CRIS","")) | E2: =TEXTJOIN(", ";TRUE,IF(Calendario!C3<>"","SUSANNA("&Calendario!C3&")",""), IF(Calendario!D3<>"","ZUA("&Calendario!D3&")",""), IF(Calendario!E3<>"","PEPE("&Calendario!E3&")",""), IF(Calendario!F3<>"","ANTO("&Calendario!F3&")",""), IF(Calendario!G3<>"","ELIAS("&Calendario!G3&")",""), IF(Calendario!H3<>"","CRIS("&Calendario!H3&")",""))
A3: 2 | B3: 46205 | C3: Jue | D3: =TEXTJOIN(", ";TRUE,IF(Calendario!C4="","SUSANNA",""), IF(Calendario!D4="","ZUA",""), IF(Calendario!E4="","PEPE",""), IF(Calendario!F4="","ANTO",""), IF(Calendario!G4="","ELIAS",""), IF(Calendario!H4="","CRIS","")) | E3: =TEXTJOIN(", ";TRUE,IF(Calendario!C4<>"","SUSANNA("&Calendario!C4&")",""), IF(Calendario!D4<>"","ZUA("&Calendario!D4&")",""), IF(Calendario!E4<>"","PEPE("&Calendario!E4&")",""), IF(Calendario!F4<>"","ANTO("&Calendario!F4&")",""), IF(Calendario!G4<>"","ELIAS("&Calendario!G4&")",""), IF(Calendario!H4<>"","CRIS("&Calendario!H4&")",""))
A4: 3 | B4: 46206 | C4: Vie | D4: =TEXTJOIN(", ";TRUE,IF(Calendario!C5="","SUSANNA",""), IF(Calendario!D5="","ZUA",""), IF(Calendario!E5="","PEPE",""), IF(Calendario!F5="","ANTO",""), IF(Calendario!G5="","ELIAS",""), IF(Calendario!H5="","CRIS","")) | E4: =TEXTJOIN(", ";TRUE,IF(Calendario!C5<>"","SUSANNA("&Calendario!C5&")",""), IF(Calendario!D5<>"","ZUA("&Calendario!D5&")",""), IF(Calendario!E5<>"","PEPE("&Calendario!E5&")",""), IF(Calendario!F5<>"","ANTO("&Calendario!F5&")",""), IF(Calendario!G5<>"","ELIAS("&Calendario!G5&")",""), IF(Calendario!H5<>"","CRIS("&Calendario!H5&")",""))
A5: 4 | B5: 46207 | C5: Sab | D5: =TEXTJOIN(", ";TRUE,IF(Calendario!C6="","SUSANNA",""), IF(Calendario!D6="","ZUA",""), IF(Calendario!E6="","PEPE",""), IF(Calendario!F6="","ANTO",""), IF(Calendario!G6="","ELIAS",""), IF(Calendario!H6="","CRIS","")) | E5: =TEXTJOIN(", ";TRUE,IF(Calendario!C6<>"","SUSANNA("&Calendario!C6&")",""), IF(Calendario!D6<>"","ZUA("&Calendario!D6&")",""), IF(Calendario!E6<>"","PEPE("&Calendario!E6&")",""), IF(Calendario!F6<>"","ANTO("&Calendario!F6&")",""), IF(Calendario!G6<>"","ELIAS("&Calendario!G6&")",""), IF(Calendario!H6<>"","CRIS("&Calendario!H6&")",""))
A6: 5 | B6: 46208 | C6: Dom | D6: =TEXTJOIN(", ";TRUE,IF(Calendario!C7="","SUSANNA",""), IF(Calendario!D7="","ZUA",""), IF(Calendario!E7="","PEPE",""), IF(Calendario!F7="","ANTO",""), IF(Calendario!G7="","ELIAS",""), IF(Calendario!H7="","CRIS","")) | E6: =TEXTJOIN(", ";TRUE,IF(Calendario!C7<>"","SUSANNA("&Calendario!C7&")",""), IF(Calendario!D7<>"","ZUA("&Calendario!D7&")",""), IF(Calendario!E7<>"","PEPE("&Calendario!E7&")",""), IF(Calendario!F7<>"","ANTO("&Calendario!F7&")",""), IF(Calendario!G7<>"","ELIAS("&Calendario!G7&")",""), IF(Calendario!H7<>"","CRIS("&Calendario!H7&")",""))
A7: 6 | B7: 46209 | C7: Lun | D7: =TEXTJOIN(", ";TRUE,IF(Calendario!C8="","SUSANNA",""), IF(Calendario!D8="","ZUA",""), IF(Calendario!E8="","PEPE",""), IF(Calendario!F8="","ANTO",""), IF(Calendario!G8="","ELIAS",""), IF(Calendario!H8="","CRIS","")) | E7: =TEXTJOIN(", ";TRUE,IF(Calendario!C8<>"","SUSANNA("&Calendario!C8&")",""), IF(Calendario!D8<>"","ZUA("&Calendario!D8&")",""), IF(Calendario!E8<>"","PEPE("&Calendario!E8&")",""), IF(Calendario!F8<>"","ANTO("&Calendario!F8&")",""), IF(Calendario!G8<>"","ELIAS("&Calendario!G8&")",""), IF(Calendario!H8<>"","CRIS("&Calendario!H8&")",""))
A8: 7 | B8: 46210 | C8: Mar | D8: =TEXTJOIN(", ";TRUE,IF(Calendario!C9="","SUSANNA",""), IF(Calendario!D9="","ZUA",""), IF(Calendario!E9="","PEPE",""), IF(Calendario!F9="","ANTO",""), IF(Calendario!G9="","ELIAS",""), IF(Calendario!H9="","CRIS","")) | E8: =TEXTJOIN(", ";TRUE,IF(Calendario!C9<>"","SUSANNA("&Calendario!C9&")",""), IF(Calendario!D9<>"","ZUA("&Calendario!D9&")",""), IF(Calendario!E9<>"","PEPE("&Calendario!E9&")",""), IF(Calendario!F9<>"","ANTO("&Calendario!F9&")",""), IF(Calendario!G9<>"","ELIAS("&Calendario!G9&")",""), IF(Calendario!H9<>"","CRIS("&Calendario!H9&")",""))
A9: 8 | B9: 46211 | C9: Mie | D9: =TEXTJOIN(", ";TRUE,IF(Calendario!C10="","SUSANNA",""), IF(Calendario!D10="","ZUA",""), IF(Calendario!E10="","PEPE",""), IF(Calendario!F10="","ANTO",""), IF(Calendario!G10="","ELIAS",""), IF(Calendario!H10="","CRIS","")) | E9: =TEXTJOIN(", ";TRUE,IF(Calendario!C10<>"","SUSANNA("&Calendario!C10&")",""), IF(Calendario!D10<>"","ZUA("&Calendario!D10&")",""), IF(Calendario!E10<>"","PEPE("&Calendario!E10&")",""), IF(Calendario!F10<>"","ANTO("&Calendario!F10&")",""), IF(Calendario!G10<>"","ELIAS("&Calendario!G10&")",""), IF(Calendario!H10<>"","CRIS("&Calendario!H10&")",""))
A10: 9 | B10: 46212 | C10: Jue | D10: =TEXTJOIN(", ";TRUE,IF(Calendario!C11="","SUSANNA",""), IF(Calendario!D11="","ZUA",""), IF(Calendario!E11="","PEPE",""), IF(Calendario!F11="","ANTO",""), IF(Calendario!G11="","ELIAS",""), IF(Calendario!H11="","CRIS","")) | E10: =TEXTJOIN(", ";TRUE,IF(Calendario!C11<>"","SUSANNA("&Calendario!C11&")",""), IF(Calendario!D11<>"","ZUA("&Calendario!D11&")",""), IF(Calendario!E11<>"","PEPE("&Calendario!E11&")",""), IF(Calendario!F11<>"","ANTO("&Calendario!F11&")",""), IF(Calendario!G11<>"","ELIAS("&Calendario!G11&")",""), IF(Calendario!H11<>"","CRIS("&Calendario!H11&")",""))
A11: 10 | B11: 46213 | C11: Vie | D11: =TEXTJOIN(", ";TRUE,IF(Calendario!C12="","SUSANNA",""), IF(Calendario!D12="","ZUA",""), IF(Calendario!E12="","PEPE",""), IF(Calendario!F12="","ANTO",""), IF(Calendario!G12="","ELIAS",""), IF(Calendario!H12="","CRIS","")) | E11: =TEXTJOIN(", ";TRUE,IF(Calendario!C12<>"","SUSANNA("&Calendario!C12&")",""), IF(Calendario!D12<>"","ZUA("&Calendario!D12&")",""), IF(Calendario!E12<>"","PEPE("&Calendario!E12&")",""), IF(Calendario!F12<>"","ANTO("&Calendario!F12&")",""), IF(Calendario!G12<>"","ELIAS("&Calendario!G12&")",""), IF(Calendario!H12<>"","CRIS("&Calendario!H12&")",""))
A12: 11 | B12: 46214 | C12: Sab | D12: =TEXTJOIN(", ";TRUE,IF(Calendario!C13="","SUSANNA",""), IF(Calendario!D13="","ZUA",""), IF(Calendario!E13="","PEPE",""), IF(Calendario!F13="","ANTO",""), IF(Calendario!G13="","ELIAS",""), IF(Calendario!H13="","CRIS","")) | E12: =TEXTJOIN(", ";TRUE,IF(Calendario!C13<>"","SUSANNA("&Calendario!C13&")",""), IF(Calendario!D13<>"","ZUA("&Calendario!D13&")",""), IF(Calendario!E13<>"","PEPE("&Calendario!E13&")",""), IF(Calendario!F13<>"","ANTO("&Calendario!F13&")",""), IF(Calendario!G13<>"","ELIAS("&Calendario!G13&")",""), IF(Calendario!H13<>"","CRIS("&Calendario!H13&")",""))
A13: 12 | B13: 46215 | C13: Dom | D13: =TEXTJOIN(", ";TRUE,IF(Calendario!C14="","SUSANNA",""), IF(Calendario!D14="","ZUA",""), IF(Calendario!E14="","PEPE",""), IF(Calendario!F14="","ANTO",""), IF(Calendario!G14="","ELIAS",""), IF(Calendario!H14="","CRIS","")) | E13: =TEXTJOIN(", ";TRUE,IF(Calendario!C14<>"","SUSANNA("&Calendario!C14&")",""), IF(Calendario!D14<>"","ZUA("&Calendario!D14&")",""), IF(Calendario!E14<>"","PEPE("&Calendario!E14&")",""), IF(Calendario!F14<>"","ANTO("&Calendario!F14&")",""), IF(Calendario!G14<>"","ELIAS("&Calendario!G14&")",""), IF(Calendario!H14<>"","CRIS("&Calendario!H14&")",""))
... A32: 31 | B32: 46234 | C32: Vie | D32: =TEXTJOIN(", ";TRUE,IF(Calendario!C33="","SUSANNA",""), IF(Calendario!D33="","ZUA",""), IF(Calendario!E33="","PEPE",""), IF(Calendario!F33="","ANTO",""), IF(Calendario!G33="","ELIAS",""), IF(Calendario!H33="","CRIS","")) | E32: =TEXTJOIN(", ";TRUE,IF(Calendario!C33<>"","SUSANNA("&Calendario!C33&")",""), IF(Calendario!D33<>"","ZUA("&Calendario!D33&")",""), IF(Calendario!E33<>"","PEPE("&Calendario!E33&")",""), IF(Calendario!F33<>"","ANTO("&Calendario!F33&")",""), IF(Calendario!G33<>"","ELIAS("&Calendario!G33&")",""), IF(Calendario!H33<>"","CRIS("&Calendario!H33&")",""))

Sheet Agosto
A1: AGOSTO 2026 — Quien puede cada dia
A2: 1 | B2: 46235 | C2: Sab | D2: =TEXTJOIN(", ";TRUE,IF(Calendario!C35="","SUSANNA",""), IF(Calendario!D35="","ZUA",""), IF(Calendario!E35="","PEPE",""), IF(Calendario!F35="","ANTO",""), IF(Calendario!G35="","ELIAS",""), IF(Calendario!H35="","CRIS","")) | E2: =TEXTJOIN(", ";TRUE,IF(Calendario!C35<>"","SUSANNA("&Calendario!C35&")",""), IF(Calendario!D35<>"","ZUA("&Calendario!D35&")",""), IF(Calendario!E35<>"","PEPE("&Calendario!E35&")",""), IF(Calendario!F35<>"","ANTO("&Calendario!F35&")",""), IF(Calendario!G35<>"","ELIAS("&Calendario!G35&")",""), IF(Calendario!H35<>"","CRIS("&Calendario!H35&")",""))
A3: 2 | B3: 46236 | C3: Dom | D3: =TEXTJOIN(", ";TRUE,IF(Calendario!C36="","SUSANNA",""), IF(Calendario!D36="","ZUA",""), IF(Calendario!E36="","PEPE",""), IF(Calendario!F36="","ANTO",""), IF(Calendario!G36="","ELIAS",""), IF(Calendario!H36="","CRIS","")) | E3: =TEXTJOIN(", ";TRUE,IF(Calendario!C36<>"","SUSANNA("&Calendario!C36&")",""), IF(Calendario!D36<>"","ZUA("&Calendario!D36&")",""), IF(Calendario!E36<>"","PEPE("&Calendario!E36&")",""), IF(Calendario!F36<>"","ANTO("&Calendario!F36&")",""), IF(Calendario!G36<>"","ELIAS("&Calendario!G36&")",""), IF(Calendario!H36<>"","CRIS("&Calendario!H36&")",""))
A4: 3 | B4: 46237 | C4: Lun | D4: =TEXTJOIN(", ";TRUE,IF(Calendario!C37="","SUSANNA",""), IF(Calendario!D37="","ZUA",""), IF(Calendario!E37="","PEPE",""), IF(Calendario!F37="","ANTO",""), IF(Calendario!G37="","ELIAS",""), IF(Calendario!H37="","CRIS","")) | E4: =TEXTJOIN(", ";TRUE,IF(Calendario!C37<>"","SUSANNA("&Calendario!C37&")",""), IF(Calendario!D37<>"","ZUA("&Calendario!D37&")",""), IF(Calendario!E37<>"","PEPE("&Calendario!E37&")",""), IF(Calendario!F37<>"","ANTO("&Calendario!F37&")",""), IF(Calendario!G37<>"","ELIAS("&Calendario!G37&")",""), IF(Calendario!H37<>"","CRIS("&Calendario!H37&")",""))
A5: 4 | B5: 46238 | C5: Mar | D5: =TEXTJOIN(", ";TRUE,IF(Calendario!C38="","SUSANNA",""), IF(Calendario!D38="","ZUA",""), IF(Calendario!E38="","PEPE",""), IF(Calendario!F38="","ANTO",""), IF(Calendario!G38="","ELIAS",""), IF(Calendario!H38="","CRIS","")) | E5: =TEXTJOIN(", ";TRUE,IF(Calendario!C38<>"","SUSANNA("&Calendario!C38&")",""), IF(Calendario!D38<>"","ZUA("&Calendario!D38&")",""), IF(Calendario!E38<>"","PEPE("&Calendario!E38&")",""), IF(Calendario!F38<>"","ANTO("&Calendario!F38&")",""), IF(Calendario!G38<>"","ELIAS("&Calendario!G38&")",""), IF(Calendario!H38<>"","CRIS("&Calendario!H38&")",""))
A6: 5 | B6: 46239 | C6: Mie | D6: =TEXTJOIN(", ";TRUE,IF(Calendario!C39="","SUSANNA",""), IF(Calendario!D39="","ZUA",""), IF(Calendario!E39="","PEPE",""), IF(Calendario!F39="","ANTO",""), IF(Calendario!G39="","ELIAS",""), IF(Calendario!H39="","CRIS","")) | E6: =TEXTJOIN(", ";TRUE,IF(Calendario!C39<>"","SUSANNA("&Calendario!C39&")",""), IF(Calendario!D39<>"","ZUA("&Calendario!D39&")",""), IF(Calendario!E39<>"","PEPE("&Calendario!E39&")",""), IF(Calendario!F39<>"","ANTO("&Calendario!F39&")",""), IF(Calendario!G39<>"","ELIAS("&Calendario!G39&")",""), IF(Calendario!H39<>"","CRIS("&Calendario!H39&")",""))
A7: 6 | B7: 46240 | C7: Jue | D7: =TEXTJOIN(", ";TRUE,IF(Calendario!C40="","SUSANNA",""), IF(Calendario!D40="","ZUA",""), IF(Calendario!E40="","PEPE",""), IF(Calendario!F40="","ANTO",""), IF(Calendario!G40="","ELIAS",""), IF(Calendario!H40="","CRIS","")) | E7: =TEXTJOIN(", ";TRUE,IF(Calendario!C40<>"","SUSANNA("&Calendario!C40&")",""), IF(Calendario!D40<>"","ZUA("&Calendario!D40&")",""), IF(Calendario!E40<>"","PEPE("&Calendario!E40&")",""), IF(Calendario!F40<>"","ANTO("&Calendario!F40&")",""), IF(Calendario!G40<>"","ELIAS("&Calendario!G40&")",""), IF(Calendario!H40<>"","CRIS("&Calendario!H40&")",""))
A8: 7 | B8: 46241 | C8: Vie | D8: =TEXTJOIN(", ";TRUE,IF(Calendario!C41="","SUSANNA",""), IF(Calendario!D41="","ZUA",""), IF(Calendario!E41="","PEPE",""), IF(Calendario!F41="","ANTO",""), IF(Calendario!G41="","ELIAS",""), IF(Calendario!H41="","CRIS","")) | E8: =TEXTJOIN(", ";TRUE,IF(Calendario!C41<>"","SUSANNA("&Calendario!C41&")",""), IF(Calendario!D41<>"","ZUA("&Calendario!D41&")",""), IF(Calendario!E41<>"","PEPE("&Calendario!E41&")",""), IF(Calendario!F41<>"","ANTO("&Calendario!F41&")",""), IF(Calendario!G41<>"","ELIAS("&Calendario!G41&")",""), IF(Calendario!H41<>"","CRIS("&Calendario!H41&")",""))
A9: 8 | B9: 46242 | C9: Sab | D9: =TEXTJOIN(", ";TRUE,IF(Calendario!C42="","SUSANNA",""), IF(Calendario!D42="","ZUA",""), IF(Calendario!E42="","PEPE",""), IF(Calendario!F42="","ANTO",""), IF(Calendario!G42="","ELIAS",""), IF(Calendario!H42="","CRIS","")) | E9: =TEXTJOIN(", ";TRUE,IF(Calendario!C42<>"","SUSANNA("&Calendario!C42&")",""), IF(Calendario!D42<>"","ZUA("&Calendario!D42&")",""), IF(Calendario!E42<>"","PEPE("&Calendario!E42&")",""), IF(Calendario!F42<>"","ANTO("&Calendario!F42&")",""), IF(Calendario!G42<>"","ELIAS("&Calendario!G42&")",""), IF(Calendario!H42<>"","CRIS("&Calendario!H42&")",""))
A10: 9 | B10: 46243 | C10: Dom | D10: =TEXTJOIN(", ";TRUE,IF(Calendario!C43="","SUSANNA",""), IF(Calendario!D43="","ZUA",""), IF(Calendario!E43="","PEPE",""), IF(Calendario!F43="","ANTO",""), IF(Calendario!G43="","ELIAS",""), IF(Calendario!H43="","CRIS","")) | E10: =TEXTJOIN(", ";TRUE,IF(Calendario!C43<>"","SUSANNA("&Calendario!C43&")",""), IF(Calendario!D43<>"","ZUA("&Calendario!D43&")",""), IF(Calendario!E43<>"","PEPE("&Calendario!E43&")",""), IF(Calendario!F43<>"","ANTO("&Calendario!F43&")",""), IF(Calendario!G43<>"","ELIAS("&Calendario!G43&")",""), IF(Calendario!H43<>"","CRIS("&Calendario!H43&")",""))
A11: 10 | B11: 46244 | C11: Lun | D11: =TEXTJOIN(", ";TRUE,IF(Calendario!C44="","SUSANNA",""), IF(Calendario!D44="","ZUA",""), IF(Calendario!E44="","PEPE",""), IF(Calendario!F44="","ANTO",""), IF(Calendario!G44="","ELIAS",""), IF(Calendario!H44="","CRIS","")) | E11: =TEXTJOIN(", ";TRUE,IF(Calendario!C44<>"","SUSANNA("&Calendario!C44&")",""), IF(Calendario!D44<>"","ZUA("&Calendario!D44&")",""), IF(Calendario!E44<>"","PEPE("&Calendario!E44&")",""), IF(Calendario!F44<>"","ANTO("&Calendario!F44&")",""), IF(Calendario!G44<>"","ELIAS("&Calendario!G44&")",""), IF(Calendario!H44<>"","CRIS("&Calendario!H44&")",""))
A12: 11 | B12: 46245 | C12: Mar | D12: =TEXTJOIN(", ";TRUE,IF(Calendario!C45="","SUSANNA",""), IF(Calendario!D45="","ZUA",""), IF(Calendario!E45="","PEPE",""), IF(Calendario!F45="","ANTO",""), IF(Calendario!G45="","ELIAS",""), IF(Calendario!H45="","CRIS","")) | E12: =TEXTJOIN(", ";TRUE,IF(Calendario!C45<>"","SUSANNA("&Calendario!C45&")",""), IF(Calendario!D45<>"","ZUA("&Calendario!D45&")",""), IF(Calendario!E45<>"","PEPE("&Calendario!E45&")",""), IF(Calendario!F45<>"","ANTO("&Calendario!F45&")",""), IF(Calendario!G45<>"","ELIAS("&Calendario!G45&")",""), IF(Calendario!H45<>"","CRIS("&Calendario!H45&")",""))
A13: 12 | B13: 46246 | C13: Mie | D13: =TEXTJOIN(", ";TRUE,IF(Calendario!C46="","SUSANNA",""), IF(Calendario!D46="","ZUA",""), IF(Calendario!E46="","PEPE",""), IF(Calendario!F46="","ANTO",""), IF(Calendario!G46="","ELIAS",""), IF(Calendario!H46="","CRIS","")) | E13: =TEXTJOIN(", ";TRUE,IF(Calendario!C46<>"","SUSANNA("&Calendario!C46&")",""), IF(Calendario!D46<>"","ZUA("&Calendario!D46&")",""), IF(Calendario!E46<>"","PEPE("&Calendario!E46&")",""), IF(Calendario!F46<>"","ANTO("&Calendario!F46&")",""), IF(Calendario!G46<>"","ELIAS("&Calendario!G46&")",""), IF(Calendario!H46<>"","CRIS("&Calendario!H46&")",""))
... A32: 31 | B32: 46265 | C32: Lun | D32: =TEXTJOIN(", ";TRUE,IF(Calendario!C65="","SUSANNA",""), IF(Calendario!D65="","ZUA",""), IF(Calendario!E65="","PEPE",""), IF(Calendario!F65="","ANTO",""), IF(Calendario!G65="","ELIAS",""), IF(Calendario!H65="","CRIS","")) | E32: =TEXTJOIN(", ";TRUE,IF(Calendario!C65<>"","SUSANNA("&Calendario!C65&")",""), IF(Calendario!D65<>"","ZUA("&Calendario!D65&")",""), IF(Calendario!E65<>"","PEPE("&Calendario!E65&")",""), IF(Calendario!F65<>"","ANTO("&Calendario!F65&")",""), IF(Calendario!G65<>"","ELIAS("&Calendario!G65&")",""), IF(Calendario!H65<>"","CRIS("&Calendario!H65&")",""))

Sheet Cuadricula
A1: JULIO 2026
A2: Lun | B2: Mar | C2: Mie | D2: Jue | E2: Vie | F2: Sab | G2: Dom
C3: =TEXTJOIN(CHAR(10);TRUE;TEXT(Calendario!A3,"DD"),IF(Calendario!C3="";"🟢 SUSANNA";""),IF(Calendario!C3="CL";"🟤 SUSANNA(CL)";""),IF(Calendario!C3="FV";"🟡 SUSANNA(FV)";""),IF(Calendario!C3="TM";"🔵 SUSANNA(TM)";""),IF(Calendario!C3="TN";"🟣 SUSANNA(TN)";""),IF(Calendario!C3="TT";"🟠 SUSANNA(TT)";""),IF(Calendario!D3="";"🟢 ZUA";""),IF(Calendario!D3="CL";"🟤 ZUA(CL)";""),IF(Calendario!D3="FV";"🟡 ZUA(FV)";""),IF(Calendario!D3="TM";"🔵 ZUA(TM)";""),IF(Calendario!D3="TN";"🟣 ZUA(TN)";""),IF(Calendario!D3="TT";"🟠 ZUA(TT)";""),IF(Calendario!E3="";"🟢 PEPE";""),IF(Calendario!E3="CL";"🟤 PEPE(CL)";""),IF(Calendario!E3="FV";"🟡 PEPE(FV)";""),IF(Calendario!E3="TM";"🔵 PEPE(TM)";""),IF(Calendario!E3="TN";"🟣 PEPE(TN)";""),IF(Calendario!E3="TT";"🟠 PEPE(TT)";""),IF(Calendario!F3="";"🟢 ANTO";""),IF(Calendario!F3="CL";"🟤 ANTO(CL)";""),IF(Calendario!F3="FV";"🟡 ANTO(FV)";""),IF(Calendario!F3="TM";"🔵 ANTO(TM)";""),IF(Calendario!F3="TN";"🟣 ANTO(TN)";""),IF(Calendario!F3="TT";"🟠 ANTO(TT)";""),IF(Calendario!G3="";"🟢 ELIAS";""),IF(Calendario!G3="CL";"🟤 ELIAS(CL)";""),IF(Calendario!G3="FV";"🟡 ELIAS(FV)";""),IF(Calendario!G3="TM";"🔵 ELIAS(TM)";""),IF(Calendario!G3="TN";"🟣 ELIAS(TN)";""),IF(Calendario!G3="TT";"🟠 ELIAS(TT)";""),IF(Calendario!H3="";"🟢 CRIS";""),IF(Calendario!H3="CL";"🟤 CRIS(CL)";""),IF(Calendario!H3="FV";"🟡 CRIS(FV)";""),IF(Calendario!H3="TM";"🔵 CRIS(TM)";""),IF(Calendario!H3="TN";"🟣 CRIS(TN)";""),IF(Calendario!H3="TT";"🟠 CRIS(TT)";"")) | D3: =TEXTJOIN(CHAR(10);TRUE;TEXT(Calendario!A4,"DD"),IF(Calendario!C4="";"🟢 SUSANNA";""),IF(Calendario!C4="CL";"🟤 SUSANNA(CL)";""),IF(Calendario!C4="FV";"🟡 SUSANNA(FV)";""),IF(Calendario!C4="TM";"🔵 SUSANNA(TM)";""),IF(Calendario!C4="TN";"🟣 SUSANNA(TN)";""),IF(Calendario!C4="TT";"🟠 SUSANNA(TT)";""),IF(Calendario!D4="";"🟢 ZUA";""),IF(Calendario!D4="CL";"🟤 ZUA(CL)";""),IF(Calendario!D4="FV";"🟡 ZUA(FV)";""),IF(Calendario!D4="TM";"🔵 ZUA(TM)";""),IF(Calendario!D4="TN";"🟣 ZUA(TN)";""),IF(Calendario!D4="TT";"🟠 ZUA(TT)";""),IF(Calendario!E4="";"🟢 PEPE";""),IF(Calendario!E4="CL";"🟤 PEPE(CL)";""),IF(Calendario!E4="FV";"🟡 PEPE(FV)";""),IF(Calendario!E4="TM";"🔵 PEPE(TM)";""),IF(Calendario!E4="TN";"🟣 PEPE(TN)";""),IF(Calendario!E4="TT";"🟠 PEPE(TT)";""),IF(Calendario!F4="";"🟢 ANTO";""),IF(Calendario!F4="CL";"🟤 ANTO(CL)";""),IF(Calendario!F4="FV";"🟡 ANTO(FV)";""),IF(Calendario!F4="TM";"🔵 ANTO(TM)";""),IF(Calendario!F4="TN";"🟣 ANTO(TN)";""),IF(Calendario!F4="TT";"🟠 ANTO(TT)";""),IF(Calendario!G4="";"🟢 ELIAS";""),IF(Calendario!G4="CL";"🟤 ELIAS(CL)";""),IF(Calendario!G4="FV";"🟡 ELIAS(FV)";""),IF(Calendario!G4="TM";"🔵 ELIAS(TM)";""),IF(Calendario!G4="TN";"🟣 ELIAS(TN)";""),IF(Calendario!G4="TT";"🟠 ELIAS(TT)";""),IF(Calendario!H4="";"🟢 CRIS";""),IF(Calendario!H4="CL";"🟤 CRIS(CL)";""),IF(Calendario!H4="FV";"🟡 CRIS(FV)";""),IF(Calendario!H4="TM";"🔵 CRIS(TM)";""),IF(Calendario!H4="TN";"🟣 CRIS(TN)";""),IF(Calendario!H4="TT";"🟠 CRIS(TT)";"")) | E3: =TEXTJOIN(CHAR(10);TRUE;TEXT(Calendario!A5,"DD"),IF(Calendario!C5="";"🟢 SUSANNA";""),IF(Calendario!C5="CL";"🟤 SUSANNA(CL)";""),IF(Calendario!C5="FV";"🟡 SUSANNA(FV)";""),IF(Calendario!C5="TM";"🔵 SUSANNA(TM)";""),IF(Calendario!C5="TN";"🟣 SUSANNA(TN)";""),IF(Calendario!C5="TT";"🟠 SUSANNA(TT)";""),IF(Calendario!D5="";"🟢 ZUA";""),IF(Calendario!D5="CL";"🟤 ZUA(CL)";""),IF(Calendario!D5="FV";"🟡 ZUA(FV)";""),IF(Calendario!D5="TM";"🔵 ZUA(TM)";""),IF(Calendario!D5="TN";"🟣 ZUA(TN)";""),IF(Calendario!D5="TT";"🟠 ZUA(TT)";""),IF(Calendario!E5="";"🟢 PEPE";""),IF(Calendario!E5="CL";"🟤 PEPE(CL)";""),IF(Calendario!E5="FV";"🟡 PEPE(FV)";""),IF(Calendario!E5="TM";"🔵 PEPE(TM)";""),IF(Calendario!E5="TN";"🟣 PEPE(TN)";""),IF(Calendario!E5="TT";"🟠 PEPE(TT)";""),IF(Calendario!F5="";"🟢 ANTO";""),IF(Calendario!F5="CL";"🟤 ANTO(CL)";""),IF(Calendario!F5="FV";"🟡 ANTO(FV)";""),IF(Calendario!F5="TM";"🔵 ANTO(TM)";""),IF(Calendario!F5="TN";"🟣 ANTO(TN)";""),IF(Calendario!F5="TT";"🟠 ANTO(TT)";""),IF(Calendario!G5="";"🟢 ELIAS";""),IF(Calendario!G5="CL";"🟤 ELIAS(CL)";""),IF(Calendario!G5="FV";"🟡 ELIAS(FV)";""),IF(Calendario!G5="TM";"🔵 ELIAS(TM)";""),IF(Calendario!G5="TN";"🟣 ELIAS(TN)";""),IF(Calendario!G5="TT";"🟠 ELIAS(TT)";""),IF(Calendario!H5="";"🟢 CRIS";""),IF(Calendario!H5="CL";"🟤 CRIS(CL)";""),IF(Calendario!H5="FV";"🟡 CRIS(FV)";""),IF(Calendario!H5="TM";"🔵 CRIS(TM)";""),IF(Calendario!H5="TN";"🟣 CRIS(TN)";""),IF(Calendario!H5="TT";"🟠 CRIS(TT)";"")) | F3: =TEXTJOIN(CHAR(10);TRUE;TEXT(Calendario!A6,"DD"),IF(Calendario!C6="";"🟢 SUSANNA";""),IF(Calendario!C6="CL";"🟤 SUSANNA(CL)";""),IF(Calendario!C6="FV";"🟡 SUSANNA(FV)";""),IF(Calendario!C6="TM";"🔵 SUSANNA(TM)";""),IF(Calendario!C6="TN";"🟣 SUSANNA(TN)";""),IF(Calendario!C6="TT";"🟠 SUSANNA(TT)";""),IF(Calendario!D6="";"🟢 ZUA";""),IF(Calendario!D6="CL";"🟤 ZUA(CL)";""),IF(Calendario!D6="FV";"🟡 ZUA(FV)";""),IF(Calendario!D6="TM";"🔵 ZUA(TM)";""),IF(Calendario!D6="TN";"🟣 ZUA(TN)";""),IF(Calendario!D6="TT";"🟠 ZUA(TT)";""),IF(Calendario!E6="";"🟢 PEPE";""),IF(Calendario!E6="CL";"🟤 PEPE(CL)";""),IF(Calendario!E6="FV";"🟡 PEPE(FV)";""),IF(Calendario!E6="TM";"🔵 PEPE(TM)";""),IF(Calendario!E6="TN";"🟣 PEPE(TN)";""),IF(Calendario!E6="TT";"🟠 PEPE(TT)";""),IF(Calendario!F6="";"🟢 ANTO";""),IF(Calendario!F6="CL";"🟤 ANTO(CL)";""),IF(Calendario!F6="FV";"🟡 ANTO(FV)";""),IF(Calendario!F6="TM";"🔵 ANTO(TM)";""),IF(Calendario!F6="TN";"🟣 ANTO(TN)";""),IF(Calendario!F6="TT";"🟠 ANTO(TT)";""),IF(Calendario!G6="";"🟢 ELIAS";""),IF(Calendario!G6="CL";"🟤 ELIAS(CL)";""),IF(Calendario!G6="FV";"🟡 ELIAS(FV)";""),IF(Calendario!G6="TM";"🔵 ELIAS(TM)";""),IF(Calendario!G6="TN";"🟣 ELIAS(TN)";""),IF(Calendario!G6="TT";"🟠 ELIAS(TT)";""),IF(Calendario!H6="";"🟢 CRIS";""),IF(Calendario!H6="CL";"🟤 CRIS(CL)";""),IF(Calendario!H6="FV";"🟡 CRIS(FV)";""),IF(Calendario!H6="TM";"🔵 CRIS(TM)";""),IF(Calendario!H6="TN";"🟣 CRIS(TN)";""),IF(Calendario!H6="TT";"🟠 CRIS(TT)";"")) | G3: =TEXTJOIN(CHAR(10);TRUE;TEXT(Calendario!A7,"DD"),IF(Calendario!C7="";"🟢 SUSANNA";""),IF(Calendario!C7="CL";"🟤 SUSANNA(CL)";""),IF(Calendario!C7="FV";"🟡 SUSANNA(FV)";""),IF(Calendario!C7="TM";"🔵 SUSANNA(TM)";""),IF(Calendario!C7="TN";"🟣 SUSANNA(TN)";""),IF(Calendario!C7="TT";"🟠 SUSANNA(TT)";""),IF(Calendario!D7="";"🟢 ZUA";""),IF(Calendario!D7="CL";"🟤 ZUA(CL)";""),IF(Calendario!D7="FV";"🟡 ZUA(FV)";""),IF(Calendario!D7="TM";"🔵 ZUA(TM)";""),IF(Calendario!D7="TN";"🟣 ZUA(TN)";""),IF(Calendario!D7="TT";"🟠 ZUA(TT)";""),IF(Calendario!E7="";"🟢 PEPE";""),IF(Calendario!E7="CL";"🟤 PEPE(CL)";""),IF(Calendario!E7="FV";"🟡 PEPE(FV)";""),IF(Calendario!E7="TM";"🔵 PEPE(TM)";""),IF(Calendario!E7="TN";"🟣 PEPE(TN)";""),IF(Calendario!E7="TT";"🟠 PEPE(TT)";""),IF(Calendario!F7="";"🟢 ANTO";""),IF(Calendario!F7="CL";"🟤 ANTO(CL)";""),IF(Calendario!F7="FV";"🟡 ANTO(FV)";""),IF(Calendario!F7="TM";"🔵 ANTO(TM)";""),IF(Calendario!F7="TN";"🟣 ANTO(TN)";""),IF(Calendario!F7="TT";"🟠 ANTO(TT)";""),IF(Calendario!G7="";"🟢 ELIAS";""),IF(Calendario!G7="CL";"🟤 ELIAS(CL)";""),IF(Calendario!G7="FV";"🟡 ELIAS(FV)";""),IF(Calendario!G7="TM";"🔵 ELIAS(TM)";""),IF(Calendario!G7="TN";"🟣 ELIAS(TN)";""),IF(Calendario!G7="TT";"🟠 ELIAS(TT)";""),IF(Calendario!H7="";"🟢 CRIS";""),IF(Calendario!H7="CL";"🟤 CRIS(CL)";""),IF(Calendario!H7="FV";"🟡 CRIS(FV)";""),IF(Calendario!H7="TM";"🔵 CRIS(TM)";""),IF(Calendario!H7="TN";"🟣 CRIS(TN)";""),IF(Calendario!H7="TT";"🟠 CRIS(TT)";""))
A4: =TEXTJOIN(CHAR(10);TRUE;TEXT(Calendario!A8,"DD"),IF(Calendario!C8="";"🟢 SUSANNA";""),IF(Calendario!C8="CL";"🟤 SUSANNA(CL)";""),IF(Calendario!C8="FV";"🟡 SUSANNA(FV)";""),IF(Calendario!C8="TM";"🔵 SUSANNA(TM)";""),IF(Calendario!C8="TN";"🟣 SUSANNA(TN)";""),IF(Calendario!C8="TT";"🟠 SUSANNA(TT)";""),IF(Calendario!D8="";"🟢 ZUA";""),IF(Calendario!D8="CL";"🟤 ZUA(CL)";""),IF(Calendario!D8="FV";"🟡 ZUA(FV)";""),IF(Calendario!D8="TM";"🔵 ZUA(TM)";""),IF(Calendario!D8="TN";"🟣 ZUA(TN)";""),IF(Calendario!D8="TT";"🟠 ZUA(TT)";""),IF(Calendario!E8="";"🟢 PEPE";""),IF(Calendario!E8="CL";"🟤 PEPE(CL)";""),IF(Calendario!E8="FV";"🟡 PEPE(FV)";""),IF(Calendario!E8="TM";"🔵 PEPE(TM)";""),IF(Calendario!E8="TN";"🟣 PEPE(TN)";""),IF(Calendario!E8="TT";"🟠 PEPE(TT)";""),IF(Calendario!F8="";"🟢 ANTO";""),IF(Calendario!F8="CL";"🟤 ANTO(CL)";""),IF(Calendario!F8="FV";"🟡 ANTO(FV)";""),IF(Calendario!F8="TM";"🔵 ANTO(TM)";""),IF(Calendario!F8="TN";"🟣 ANTO(TN)";""),IF(Calendario!F8="TT";"🟠 ANTO(TT)";""),IF(Calendario!G8="";"🟢 ELIAS";""),IF(Calendario!G8="CL";"🟤 ELIAS(CL)";""),IF(Calendario!G8="FV";"🟡 ELIAS(FV)";""),IF(Calendario!G8="TM";"🔵 ELIAS(TM)";""),IF(Calendario!G8="TN";"🟣 ELIAS(TN)";""),IF(Calendario!G8="TT";"🟠 ELIAS(TT)";""),IF(Calendario!H8="";"🟢 CRIS";""),IF(Calendario!H8="CL";"🟤 CRIS(CL)";""),IF(Calendario!H8="FV";"🟡 CRIS(FV)";""),IF(Calendario!H8="TM";"🔵 CRIS(TM)";""),IF(Calendario!H8="TN";"🟣 CRIS(TN)";""),IF(Calendario!H8="TT";"🟠 CRIS(TT)";"")) | B4: =TEXTJOIN(CHAR(10);TRUE;TEXT(Calendario!A9,"DD"),IF(Calendario!C9="";"🟢 SUSANNA";""),IF(Calendario!C9="CL";"🟤 SUSANNA(CL)";""),IF(Calendario!C9="FV";"🟡 SUSANNA(FV)";""),IF(Calendario!C9="TM";"🔵 SUSANNA(TM)";""),IF(Calendario!C9="TN";"🟣 SUSANNA(TN)";""),IF(Calendario!C9="TT";"🟠 SUSANNA(TT)";""),IF(Calendario!D9="";"🟢 ZUA";""),IF(Calendario!D9="CL";"🟤 ZUA(CL)";""),IF(Calendario!D9="FV";"🟡 ZUA(FV)";""),IF(Calendario!D9="TM";"🔵 ZUA(TM)";""),IF(Calendario!D9="TN";"🟣 ZUA(TN)";""),IF(Calendario!D9="TT";"🟠 ZUA(TT)";""),IF(Calendario!E9="";"🟢 PEPE";""),IF(Calendario!E9="CL";"🟤 PEPE(CL)";""),IF(Calendario!E9="FV";"🟡 PEPE(FV)";""),IF(Calendario!E9="TM";"🔵 PEPE(TM)";""),IF(Calendario!E9="TN";"🟣 PEPE(TN)";""),IF(Calendario!E9="TT";"🟠 PEPE(TT)";""),IF(Calendario!F9="";"🟢 ANTO";""),IF(Calendario!F9="CL";"🟤 ANTO(CL)";""),IF(Calendario!F9="FV";"🟡 ANTO(FV)";""),IF(Calendario!F9="TM";"🔵 ANTO(TM)";""),IF(Calendario!F9="TN";"🟣 ANTO(TN)";""),IF(Calendario!F9="TT";"🟠 ANTO(TT)";""),IF(Calendario!G9="";"🟢 ELIAS";""),IF(Calendario!G9="CL";"🟤 ELIAS(CL)";""),IF(Calendario!G9="FV";"🟡 ELIAS(FV)";""),IF(Calendario!G9="TM";"🔵 ELIAS(TM)";""),IF(Calendario!G9="TN";"🟣 ELIAS(TN)";""),IF(Calendario!G9="TT";"🟠 ELIAS(TT)";""),IF(Calendario!H9="";"🟢 CRIS";""),IF(Calendario!H9="CL";"🟤 CRIS(CL)";""),IF(Calendario!H9="FV";"🟡 CRIS(FV)";""),IF(Calendario!H9="TM";"🔵 CRIS(TM)";""),IF(Calendario!H9="TN";"🟣 CRIS(TN)";""),IF(Calendario!H9="TT";"🟠 CRIS(TT)";"")) | C4: =TEXTJOIN(CHAR(10);TRUE;TEXT(Calendario!A10,"DD"),IF(Calendario!C10="";"🟢 SUSANNA";""),IF(Calendario!C10="CL";"🟤 SUSANNA(CL)";""),IF(Calendario!C10="FV";"🟡 SUSANNA(FV)";""),IF(Calendario!C10="TM";"🔵 SUSANNA(TM)";""),IF(Calendario!C10="TN";"🟣 SUSANNA(TN)";""),IF(Calendario!C10="TT";"🟠 SUSANNA(TT)";""),IF(Calendario!D10="";"🟢 ZUA";""),IF(Calendario!D10="CL";"🟤 ZUA(CL)";""),IF(Calendario!D10="FV";"🟡 ZUA(FV)";""),IF(Calendario!D10="TM";"🔵 ZUA(TM)";""),IF(Calendario!D10="TN";"🟣 ZUA(TN)";""),IF(Calendario!D10="TT";"🟠 ZUA(TT)";""),IF(Calendario!E10="";"🟢 PEPE";""),IF(Calendario!E10="CL";"🟤 PEPE(CL)";""),IF(Calendario!E10="FV";"🟡 PEPE(FV)";""),IF(Calendario!E10="TM";"🔵 PEPE(TM)";""),IF(Calendario!E10="TN";"🟣 PEPE(TN)";""),IF(Calendario!E10="TT";"🟠 PEPE(TT)";""),IF(Calendario!F10="";"🟢 ANTO";""),IF(Calendario!F10="CL";"🟤 ANTO(CL)";""),IF(Calendario!F10="FV";"🟡 ANTO(FV)";""),IF(Calendario!F10="TM";"🔵 ANTO(TM)";""),IF(Calendario!F10="TN";"🟣 ANTO(TN)";""),IF(Calendario!F10="TT";"🟠 ANTO(TT)";""),IF(Calendario!G10="";"🟢 ELIAS";""),IF(Calendario!G10="CL";"🟤 ELIAS(CL)";""),IF(Calendario!G10="FV";"🟡 ELIAS(FV)";""),IF(Calendario!G10="TM";"🔵 ELIAS(TM)";""),IF(Calendario!G10="TN";"🟣 ELIAS(TN)";""),IF(Calendario!G10="TT";"🟠 ELIAS(TT)";""),IF(Calendario!H10="";"🟢 CRIS";""),IF(Calendario!H10="CL";"🟤 CRIS(CL)";""),IF(Calendario!H10="FV";"🟡 CRIS(FV)";""),IF(Calendario!H10="TM";"🔵 CRIS(TM)";""),IF(Calendario!H10="TN";"🟣 CRIS(TN)";""),IF(Calendario!H10="TT";"🟠 CRIS(TT)";"")) | D4: =TEXTJOIN(CHAR(10);TRUE;TEXT(Calendario!A11,"DD"),IF(Calendario!C11="";"🟢 SUSANNA";""),IF(Calendario!C11="CL";"🟤 SUSANNA(CL)";""),IF(Calendario!C11="FV";"🟡 SUSANNA(FV)";""),IF(Calendario!C11="TM";"🔵 SUSANNA(TM)";""),IF(Calendario!C11="TN";"🟣 SUSANNA(TN)";""),IF(Calendario!C11="TT";"🟠 SUSANNA(TT)";""),IF(Calendario!D11="";"🟢 ZUA";""),IF(Calendario!D11="CL";"🟤 ZUA(CL)";""),IF(Calendario!D11="FV";"🟡 ZUA(FV)";""),IF(Calendario!D11="TM";"🔵 ZUA(TM)";""),IF(Calendario!D11="TN";"🟣 ZUA(TN)";""),IF(Calendario!D11="TT";"🟠 ZUA(TT)";""),IF(Calendario!E11="";"🟢 PEPE";""),IF(Calendario!E11="CL";"🟤 PEPE(CL)";""),IF(Calendario!E11="FV";"🟡 PEPE(FV)";""),IF(Calendario!E11="TM";"🔵 PEPE(TM)";""),IF(Calendario!E11="TN";"🟣 PEPE(TN)";""),IF(Calendario!E11="TT";"🟠 PEPE(TT)";""),IF(Calendario!F11="";"🟢 ANTO";""),IF(Calendario!F11="CL";"🟤 ANTO(CL)";""),IF(Calendario!F11="FV";"🟡 ANTO(FV)";""),IF(Calendario!F11="TM";"🔵 ANTO(TM)";""),IF(Calendario!F11="TN";"🟣 ANTO(TN)";""),IF(Calendario!F11="TT";"🟠 ANTO(TT)";""),IF(Calendario!G11="";"🟢 ELIAS";""),IF(Calendario!G11="CL";"🟤 ELIAS(CL)";""),IF(Calendario!G11="FV";"🟡 ELIAS(FV)";""),IF(Calendario!G11="TM";"🔵 ELIAS(TM)";""),IF(Calendario!G11="TN";"🟣 ELIAS(TN)";""),IF(Calendario!G11="TT";"🟠 ELIAS(TT)";""),IF(Calendario!H11="";"🟢 CRIS";""),IF(Calendario!H11="CL";"🟤 CRIS(CL)";""),IF(Calendario!H11="FV";"🟡 CRIS(FV)";""),IF(Calendario!H11="TM";"🔵 CRIS(TM)";""),IF(Calendario!H11="TN";"🟣 CRIS(TN)";""),IF(Calendario!H11="TT";"🟠 CRIS(TT)";"")) | E4: =TEXTJOIN(CHAR(10);TRUE;TEXT(Calendario!A12,"DD"),IF(Calendario!C12="";"🟢 SUSANNA";""),IF(Calendario!C12="CL";"🟤 SUSANNA(CL)";""),IF(Calendario!C12="FV";"🟡 SUSANNA(FV)";""),IF(Calendario!C12="TM";"🔵 SUSANNA(TM)";""),IF(Calendario!C12="TN";"🟣 SUSANNA(TN)";""),IF(Calendario!C12="TT";"🟠 SUSANNA(TT)";""),IF(Calendario!D12="";"🟢 ZUA";""),IF(Calendario!D12="CL";"🟤 ZUA(CL)";""),IF(Calendario!D12="FV";"🟡 ZUA(FV)";""),IF(Calendario!D12="TM";"🔵 ZUA(TM)";""),IF(Calendario!D12="TN";"🟣 ZUA(TN)";""),IF(Calendario!D12="TT";"🟠 ZUA(TT)";""),IF(Calendario!E12="";"🟢 PEPE";""),IF(Calendario!E12="CL";"🟤 PEPE(CL)";""),IF(Calendario!E12="FV";"🟡 PEPE(FV)";""),IF(Calendario!E12="TM";"🔵 PEPE(TM)";""),IF(Calendario!E12="TN";"🟣 PEPE(TN)";""),IF(Calendario!E12="TT";"🟠 PEPE(TT)";""),IF(Calendario!F12="";"🟢 ANTO";""),IF(Calendario!F12="CL";"🟤 ANTO(CL)";""),IF(Calendario!F12="FV";"🟡 ANTO(FV)";""),IF(Calendario!F12="TM";"🔵 ANTO(TM)";""),IF(Calendario!F12="TN";"🟣 ANTO(TN)";""),IF(Calendario!F12="TT";"🟠 ANTO(TT)";""),IF(Calendario!G12="";"🟢 ELIAS";""),IF(Calendario!G12="CL";"🟤 ELIAS(CL)";""),IF(Calendario!G12="FV";"🟡 ELIAS(FV)";""),IF(Calendario!G12="TM";"🔵 ELIAS(TM)";""),IF(Calendario!G12="TN";"🟣 ELIAS(TN)";""),IF(Calendario!G12="TT";"🟠 ELIAS(TT)";""),IF(Calendario!H12="";"🟢 CRIS";""),IF(Calendario!H12="CL";"🟤 CRIS(CL)";""),IF(Calendario!H12="FV";"🟡 CRIS(FV)";""),IF(Calendario!H12="TM";"🔵 CRIS(TM)";""),IF(Calendario!H12="TN";"🟣 CRIS(TN)";""),IF(Calendario!H12="TT";"🟠 CRIS(TT)";"")) | F4: =TEXTJOIN(CHAR(10);TRUE;TEXT(Calendario!A13,"DD"),IF(Calendario!C13="";"🟢 SUSANNA";""),IF(Calendario!C13="CL";"🟤 SUSANNA(CL)";""),IF(Calendario!C13="FV";"🟡 SUSANNA(FV)";""),IF(Calendario!C13="TM";"🔵 SUSANNA(TM)";""),IF(Calendario!C13="TN";"🟣 SUSANNA(TN)";""),IF(Calendario!C13="TT";"🟠 SUSANNA(TT)";""),IF(Calendario!D13="";"🟢 ZUA";""),IF(Calendario!D13="CL";"🟤 ZUA(CL)";""),IF(Calendario!D13="FV";"🟡 ZUA(FV)";""),IF(Calendario!D13="TM";"🔵 ZUA(TM)";""),IF(Calendario!D13="TN";"🟣 ZUA(TN)";""),IF(Calendario!D13="TT";"🟠 ZUA(TT)";""),IF(Calendario!E13="";"🟢 PEPE";""),IF(Calendario!E13="CL";"🟤 PEPE(CL)";""),IF(Calendario!E13="FV";"🟡 PEPE(FV)";""),IF(Calendario!E13="TM";"🔵 PEPE(TM)";""),IF(Calendario!E13="TN";"🟣 PEPE(TN)";""),IF(Calendario!E13="TT";"🟠 PEPE(TT)";""),IF(Calendario!F13="";"🟢 ANTO";""),IF(Calendario!F13="CL";"🟤 ANTO(CL)";""),IF(Calendario!F13="FV";"🟡 ANTO(FV)";""),IF(Calendario!F13="TM";"🔵 ANTO(TM)";""),IF(Calendario!F13="TN";"🟣 ANTO(TN)";""),IF(Calendario!F13="TT";"🟠 ANTO(TT)";""),IF(Calendario!G13="";"🟢 ELIAS";""),IF(Calendario!G13="CL";"🟤 ELIAS(CL)";""),IF(Calendario!G13="FV";"🟡 ELIAS(FV)";""),IF(Calendario!G13="TM";"🔵 ELIAS(TM)";""),IF(Calendario!G13="TN";"🟣 ELIAS(TN)";""),IF(Calendario!G13="TT";"🟠 ELIAS(TT)";""),IF(Calendario!H13="";"🟢 CRIS";""),IF(Calendario!H13="CL";"🟤 CRIS(CL)";""),IF(Calendario!H13="FV";"🟡 CRIS(FV)";""),IF(Calendario!H13="TM";"🔵 CRIS(TM)";""),IF(Calendario!H13="TN";"🟣 CRIS(TN)";""),IF(Calendario!H13="TT";"🟠 CRIS(TT)";"")) | G4: =TEXTJOIN(CHAR(10);TRUE;TEXT(Calendario!A14,"DD"),IF(Calendario!C14="";"🟢 SUSANNA";""),IF(Calendario!C14="CL";"🟤 SUSANNA(CL)";""),IF(Calendario!C14="FV";"🟡 SUSANNA(FV)";""),IF(Calendario!C14="TM";"🔵 SUSANNA(TM)";""),IF(Calendario!C14="TN";"🟣 SUSANNA(TN)";""),IF(Calendario!C14="TT";"🟠 SUSANNA(TT)";""),IF(Calendario!D14="";"🟢 ZUA";""),IF(Calendario!D14="CL";"🟤 ZUA(CL)";""),IF(Calendario!D14="FV";"🟡 ZUA(FV)";""),IF(Calendario!D14="TM";"🔵 ZUA(TM)";""),IF(Calendario!D14="TN";"🟣 ZUA(TN)";""),IF(Calendario!D14="TT";"🟠 ZUA(TT)";""),IF(Calendario!E14="";"🟢 PEPE";""),IF(Calendario!E14="CL";"🟤 PEPE(CL)";""),IF(Calendario!E14="FV";"🟡 PEPE(FV)";""),IF(Calendario!E14="TM";"🔵 PEPE(TM)";""),IF(Calendario!E14="TN";"🟣 PEPE(TN)";""),IF(Calendario!E14="TT";"🟠 PEPE(TT)";""),IF(Calendario!F14="";"🟢 ANTO";""),IF(Calendario!F14="CL";"🟤 ANTO(CL)";""),IF(Calendario!F14="FV";"🟡 ANTO(FV)";""),IF(Calendario!F14="TM";"🔵 ANTO(TM)";""),IF(Calendario!F14="TN";"🟣 ANTO(TN)";""),IF(Calendario!F14="TT";"🟠 ANTO(TT)";""),IF(Calendario!G14="";"🟢 ELIAS";""),IF(Calendario!G14="CL";"🟤 ELIAS(CL)";""),IF(Calendario!G14="FV";"🟡 ELIAS(FV)";""),IF(Calendario!G14="TM";"🔵 ELIAS(TM)";""),IF(Calendario!G14="TN";"🟣 ELIAS(TN)";""),IF(Calendario!G14="TT";"🟠 ELIAS(TT)";""),IF(Calendario!H14="";"🟢 CRIS";""),IF(Calendario!H14="CL";"🟤 CRIS(CL)";""),IF(Calendario!H14="FV";"🟡 CRIS(FV)";""),IF(Calendario!H14="TM";"🔵 CRIS(TM)";""),IF(Calendario!H14="TN";"🟣 CRIS(TN)";""),IF(Calendario!H14="TT";"🟠 CRIS(TT)";""))
A5: =TEXTJOIN(CHAR(10);TRUE;TEXT(Calendario!A15,"DD"),IF(Calendario!C15="";"🟢 SUSANNA";""),IF(Calendario!C15="CL";"🟤 SUSANNA(CL)";""),IF(Calendario!C15="FV";"🟡 SUSANNA(FV)";""),IF(Calendario!C15="TM";"🔵 SUSANNA(TM)";""),IF(Calendario!C15="TN";"🟣 SUSANNA(TN)";""),IF(Calendario!C15="TT";"🟠 SUSANNA(TT)";""),IF(Calendario!D15="";"🟢 ZUA";""),IF(Calendario!D15="CL";"🟤 ZUA(CL)";""),IF(Calendario!D15="FV";"🟡 ZUA(FV)";""),IF(Calendario!D15="TM";"🔵 ZUA(TM)";""),IF(Calendario!D15="TN";"🟣 ZUA(TN)";""),IF(Calendario!D15="TT";"🟠 ZUA(TT)";""),IF(Calendario!E15="";"🟢 PEPE";""),IF(Calendario!E15="CL";"🟤 PEPE(CL)";""),IF(Calendario!E15="FV";"🟡 PEPE(FV)";""),IF(Calendario!E15="TM";"🔵 PEPE(TM)";""),IF(Calendario!E15="TN";"🟣 PEPE(TN)";""),IF(Calendario!E15="TT";"🟠 PEPE(TT)";""),IF(Calendario!F15="";"🟢 ANTO";""),IF(Calendario!F15="CL";"🟤 ANTO(CL)";""),IF(Calendario!F15="FV";"🟡 ANTO(FV)";""),IF(Calendario!F15="TM";"🔵 ANTO(TM)";""),IF(Calendario!F15="TN";"🟣 ANTO(TN)";""),IF(Calendario!F15="TT";"🟠 ANTO(TT)";""),IF(Calendario!G15="";"🟢 ELIAS";""),IF(Calendario!G15="CL";"🟤 ELIAS(CL)";""),IF(Calendario!G15="FV";"🟡 ELIAS(FV)";""),IF(Calendario!G15="TM";"🔵 ELIAS(TM)";""),IF(Calendario!G15="TN";"🟣 ELIAS(TN)";""),IF(Calendario!G15="TT";"🟠 ELIAS(TT)";""),IF(Calendario!H15="";"🟢 CRIS";""),IF(Calendario!H15="CL";"🟤 CRIS(CL)";""),IF(Calendario!H15="FV";"🟡 CRIS(FV)";""),IF(Calendario!H15="TM";"🔵 CRIS(TM)";""),IF(Calendario!H15="TN";"🟣 CRIS(TN)";""),IF(Calendario!H15="TT";"🟠 CRIS(TT)";"")) | B5: =TEXTJOIN(CHAR(10);TRUE;TEXT(Calendario!A16,"DD"),IF(Calendario!C16="";"🟢 SUSANNA";""),IF(Calendario!C16="CL";"🟤 SUSANNA(CL)";""),IF(Calendario!C16="FV";"🟡 SUSANNA(FV)";""),IF(Calendario!C16="TM";"🔵 SUSANNA(TM)";""),IF(Calendario!C16="TN";"🟣 SUSANNA(TN)";""),IF(Calendario!C16="TT";"🟠 SUSANNA(TT)";""),IF(Calendario!D16="";"🟢 ZUA";""),IF(Calendario!D16="CL";"🟤 ZUA(CL)";""),IF(Calendario!D16="FV";"🟡 ZUA(FV)";""),IF(Calendario!D16="TM";"🔵 ZUA(TM)";""),IF(Calendario!D16="TN";"🟣 ZUA(TN)";""),IF(Calendario!D16="TT";"🟠 ZUA(TT)";""),IF(Calendario!E16="";"🟢 PEPE";""),IF(Calendario!E16="CL";"🟤 PEPE(CL)";""),IF(Calendario!E16="FV";"🟡 PEPE(FV)";""),IF(Calendario!E16="TM";"🔵 PEPE(TM)";""),IF(Calendario!E16="TN";"🟣 PEPE(TN)";""),IF(Calendario!E16="TT";"🟠 PEPE(TT)";""),IF(Calendario!F16="";"🟢 ANTO";""),IF(Calendario!F16="CL";"🟤 ANTO(CL)";""),IF(Calendario!F16="FV";"🟡 ANTO(FV)";""),IF(Calendario!F16="TM";"🔵 ANTO(TM)";""),IF(Calendario!F16="TN";"🟣 ANTO(TN)";""),IF(Calendario!F16="TT";"🟠 ANTO(TT)";""),IF(Calendario!G16="";"🟢 ELIAS";""),IF(Calendario!G16="CL";"🟤 ELIAS(CL)";""),IF(Calendario!G16="FV";"🟡 ELIAS(FV)";""),IF(Calendario!G16="TM";"🔵 ELIAS(TM)";""),IF(Calendario!G16="TN";"🟣 ELIAS(TN)";""),IF(Calendario!G16="TT";"🟠 ELIAS(TT)";""),IF(Calendario!H16="";"🟢 CRIS";""),IF(Calendario!H16="CL";"🟤 CRIS(CL)";""),IF(Calendario!H16="FV";"🟡 CRIS(FV)";""),IF(Calendario!H16="TM";"🔵 CRIS(TM)";""),IF(Calendario!H16="TN";"🟣 CRIS(TN)";""),IF(Calendario!H16="TT";"🟠 CRIS(TT)";"")) | C5: =TEXTJOIN(CHAR(10);TRUE;TEXT(Calendario!A17,"DD"),IF(Calendario!C17="";"🟢 SUSANNA";""),IF(Calendario!C17="CL";"🟤 SUSANNA(CL)";""),IF(Calendario!C17="FV";"🟡 SUSANNA(FV)";""),IF(Calendario!C17="TM";"🔵 SUSANNA(TM)";""),IF(Calendario!C17="TN";"🟣 SUSANNA(TN)";""),IF(Calendario!C17="TT";"🟠 SUSANNA(TT)";""),IF(Calendario!D17="";"🟢 ZUA";""),IF(Calendario!D17="CL";"🟤 ZUA(CL)";""),IF(Calendario!D17="FV";"🟡 ZUA(FV)";""),IF(Calendario!D17="TM";"🔵 ZUA(TM)";""),IF(Calendario!D17="TN";"🟣 ZUA(TN)";""),IF(Calendario!D17="TT";"🟠 ZUA(TT)";""),IF(Calendario!E17="";"🟢 PEPE";""),IF(Calendario!E17="CL";"🟤 PEPE(CL)";""),IF(Calendario!E17="FV";"🟡 PEPE(FV)";""),IF(Calendario!E17="TM";"🔵 PEPE(TM)";""),IF(Calendario!E17="TN";"🟣 PEPE(TN)";""),IF(Calendario!E17="TT";"🟠 PEPE(TT)";""),IF(Calendario!F17="";"🟢 ANTO";""),IF(Calendario!F17="CL";"🟤 ANTO(CL)";""),IF(Calendario!F17="FV";"🟡 ANTO(FV)";""),IF(Calendario!F17="TM";"🔵 ANTO(TM)";""),IF(Calendario!F17="TN";"🟣 ANTO(TN)";""),IF(Calendario!F17="TT";"🟠 ANTO(TT)";""),IF(Calendario!G17="";"🟢 ELIAS";""),IF(Calendario!G17="CL";"🟤 ELIAS(CL)";""),IF(Calendario!G17="FV";"🟡 ELIAS(FV)";""),IF(Calendario!G17="TM";"🔵 ELIAS(TM)";""),IF(Calendario!G17="TN";"🟣 ELIAS(TN)";""),IF(Calendario!G17="TT";"🟠 ELIAS(TT)";""),IF(Calendario!H17="";"🟢 CRIS";""),IF(Calendario!H17="CL";"🟤 CRIS(CL)";""),IF(Calendario!H17="FV";"🟡 CRIS(FV)";""),IF(Calendario!H17="TM";"🔵 CRIS(TM)";""),IF(Calendario!H17="TN";"🟣 CRIS(TN)";""),IF(Calendario!H17="TT";"🟠 CRIS(TT)";"")) | D5: =TEXTJOIN(CHAR(10);TRUE;TEXT(Calendario!A18,"DD"),IF(Calendario!C18="";"🟢 SUSANNA";""),IF(Calendario!C18="CL";"🟤 SUSANNA(CL)";""),IF(Calendario!C18="FV";"🟡 SUSANNA(FV)";""),IF(Calendario!C18="TM";"🔵 SUSANNA(TM)";""),IF(Calendario!C18="TN";"🟣 SUSANNA(TN)";""),IF(Calendario!C18="TT";"🟠 SUSANNA(TT)";""),IF(Calendario!D18="";"🟢 ZUA";""),IF(Calendario!D18="CL";"🟤 ZUA(CL)";""),IF(Calendario!D18="FV";"🟡 ZUA(FV)";""),IF(Calendario!D18="TM";"🔵 ZUA(TM)";""),IF(Calendario!D18="TN";"🟣 ZUA(TN)";""),IF(Calendario!D18="TT";"🟠 ZUA(TT)";""),IF(Calendario!E18="";"🟢 PEPE";""),IF(Calendario!E18="CL";"🟤 PEPE(CL)";""),IF(Calendario!E18="FV";"🟡 PEPE(FV)";""),IF(Calendario!E18="TM";"🔵 PEPE(TM)";""),IF(Calendario!E18="TN";"🟣 PEPE(TN)";""),IF(Calendario!E18="TT";"🟠 PEPE(TT)";""),IF(Calendario!F18="";"🟢 ANTO";""),IF(Calendario!F18="CL";"🟤 ANTO(CL)";""),IF(Calendario!F18="FV";"🟡 ANTO(FV)";""),IF(Calendario!F18="TM";"🔵 ANTO(TM)";""),IF(Calendario!F18="TN";"🟣 ANTO(TN)";""),IF(Calendario!F18="TT";"🟠 ANTO(TT)";""),IF(Calendario!G18="";"🟢 ELIAS";""),IF(Calendario!G18="CL";"🟤 ELIAS(CL)";""),IF(Calendario!G18="FV";"🟡 ELIAS(FV)";""),IF(Calendario!G18="TM";"🔵 ELIAS(TM)";""),IF(Calendario!G18="TN";"🟣 ELIAS(TN)";""),IF(Calendario!G18="TT";"🟠 ELIAS(TT)";""),IF(Calendario!H18="";"🟢 CRIS";""),IF(Calendario!H18="CL";"🟤 CRIS(CL)";""),IF(Calendario!H18="FV";"🟡 CRIS(FV)";""),IF(Calendario!H18="TM";"🔵 CRIS(TM)";""),IF(Calendario!H18="TN";"🟣 CRIS(TN)";""),IF(Calendario!H18="TT";"🟠 CRIS(TT)";"")) | E5: =TEXTJOIN(CHAR(10);TRUE;TEXT(Calendario!A19,"DD"),IF(Calendario!C19="";"🟢 SUSANNA";""),IF(Calendario!C19="CL";"🟤 SUSANNA(CL)";""),IF(Calendario!C19="FV";"🟡 SUSANNA(FV)";""),IF(Calendario!C19="TM";"🔵 SUSANNA(TM)";""),IF(Calendario!C19="TN";"🟣 SUSANNA(TN)";""),IF(Calendario!C19="TT";"🟠 SUSANNA(TT)";""),IF(Calendario!D19="";"🟢 ZUA";""),IF(Calendario!D19="CL";"🟤 ZUA(CL)";""),IF(Calendario!D19="FV";"🟡 ZUA(FV)";""),IF(Calendario!D19="TM";"🔵 ZUA(TM)";""),IF(Calendario!D19="TN";"🟣 ZUA(TN)";""),IF(Calendario!D19="TT";"🟠 ZUA(TT)";""),IF(Calendario!E19="";"🟢 PEPE";""),IF(Calendario!E19="CL";"🟤 PEPE(CL)";""),IF(Calendario!E19="FV";"🟡 PEPE(FV)";""),IF(Calendario!E19="TM";"🔵 PEPE(TM)";""),IF(Calendario!E19="TN";"🟣 PEPE(TN)";""),IF(Calendario!E19="TT";"🟠 PEPE(TT)";""),IF(Calendario!F19="";"🟢 ANTO";""),IF(Calendario!F19="CL";"🟤 ANTO(CL)";""),IF(Calendario!F19="FV";"🟡 ANTO(FV)";""),IF(Calendario!F19="TM";"🔵 ANTO(TM)";""),IF(Calendario!F19="TN";"🟣 ANTO(TN)";""),IF(Calendario!F19="TT";"🟠 ANTO(TT)";""),IF(Calendario!G19="";"🟢 ELIAS";""),IF(Calendario!G19="CL";"🟤 ELIAS(CL)";""),IF(Calendario!G19="FV";"🟡 ELIAS(FV)";""),IF(Calendario!G19="TM";"🔵 ELIAS(TM)";""),IF(Calendario!G19="TN";"🟣 ELIAS(TN)";""),IF(Calendario!G19="TT";"🟠 ELIAS(TT)";""),IF(Calendario!H19="";"🟢 CRIS";""),IF(Calendario!H19="CL";"🟤 CRIS(CL)";""),IF(Calendario!H19="FV";"🟡 CRIS(FV)";""),IF(Calendario!H19="TM";"🔵 CRIS(TM)";""),IF(Calendario!H19="TN";"🟣 CRIS(TN)";""),IF(Calendario!H19="TT";"🟠 CRIS(TT)";"")) | F5: =TEXTJOIN(CHAR(10);TRUE;TEXT(Calendario!A20,"DD"),IF(Calendario!C20="";"🟢 SUSANNA";""),IF(Calendario!C20="CL";"🟤 SUSANNA(CL)";""),IF(Calendario!C20="FV";"🟡 SUSANNA(FV)";""),IF(Calendario!C20="TM";"🔵 SUSANNA(TM)";""),IF(Calendario!C20="TN";"🟣 SUSANNA(TN)";""),IF(Calendario!C20="TT";"🟠 SUSANNA(TT)";""),IF(Calendario!D20="";"🟢 ZUA";""),IF(Calendario!D20="CL";"🟤 ZUA(CL)";""),IF(Calendario!D20="FV";"🟡 ZUA(FV)";""),IF(Calendario!D20="TM";"🔵 ZUA(TM)";""),IF(Calendario!D20="TN";"🟣 ZUA(TN)";""),IF(Calendario!D20="TT";"🟠 ZUA(TT)";""),IF(Calendario!E20="";"🟢 PEPE";""),IF(Calendario!E20="CL";"🟤 PEPE(CL)";""),IF(Calendario!E20="FV";"🟡 PEPE(FV)";""),IF(Calendario!E20="TM";"🔵 PEPE(TM)";""),IF(Calendario!E20="TN";"🟣 PEPE(TN)";""),IF(Calendario!E20="TT";"🟠 PEPE(TT)";""),IF(Calendario!F20="";"🟢 ANTO";""),IF(Calendario!F20="CL";"🟤 ANTO(CL)";""),IF(Calendario!F20="FV";"🟡 ANTO(FV)";""),IF(Calendario!F20="TM";"🔵 ANTO(TM)";""),IF(Calendario!F20="TN";"🟣 ANTO(TN)";""),IF(Calendario!F20="TT";"🟠 ANTO(TT)";""),IF(Calendario!G20="";"🟢 ELIAS";""),IF(Calendario!G20="CL";"🟤 ELIAS(CL)";""),IF(Calendario!G20="FV";"🟡 ELIAS(FV)";""),IF(Calendario!G20="TM";"🔵 ELIAS(TM)";""),IF(Calendario!G20="TN";"🟣 ELIAS(TN)";""),IF(Calendario!G20="TT";"🟠 ELIAS(TT)";""),IF(Calendario!H20="";"🟢 CRIS";""),IF(Calendario!H20="CL";"🟤 CRIS(CL)";""),IF(Calendario!H20="FV";"🟡 CRIS(FV)";""),IF(Calendario!H20="TM";"🔵 CRIS(TM)";""),IF(Calendario!H20="TN";"🟣 CRIS(TN)";""),IF(Calendario!H20="TT";"🟠 CRIS(TT)";"")) | G5: =TEXTJOIN(CHAR(10);TRUE;TEXT(Calendario!A21,"DD"),IF(Calendario!C21="";"🟢 SUSANNA";""),IF(Calendario!C21="CL";"🟤 SUSANNA(CL)";""),IF(Calendario!C21="FV";"🟡 SUSANNA(FV)";""),IF(Calendario!C21="TM";"🔵 SUSANNA(TM)";""),IF(Calendario!C21="TN";"🟣 SUSANNA(TN)";""),IF(Calendario!C21="TT";"🟠 SUSANNA(TT)";""),IF(Calendario!D21="";"🟢 ZUA";""),IF(Calendario!D21="CL";"🟤 ZUA(CL)";""),IF(Calendario!D21="FV";"🟡 ZUA(FV)";""),IF(Calendario!D21="TM";"🔵 ZUA(TM)";""),IF(Calendario!D21="TN";"🟣 ZUA(TN)";""),IF(Calendario!D21="TT";"🟠 ZUA(TT)";""),IF(Calendario!E21="";"🟢 PEPE";""),IF(Calendario!E21="CL";"🟤 PEPE(CL)";""),IF(Calendario!E21="FV";"🟡 PEPE(FV)";""),IF(Calendario!E21="TM";"🔵 PEPE(TM)";""),IF(Calendario!E21="TN";"🟣 PEPE(TN)";""),IF(Calendario!E21="TT";"🟠 PEPE(TT)";""),IF(Calendario!F21="";"🟢 ANTO";""),IF(Calendario!F21="CL";"🟤 ANTO(CL)";""),IF(Calendario!F21="FV";"🟡 ANTO(FV)";""),IF(Calendario!F21="TM";"🔵 ANTO(TM)";""),IF(Calendario!F21="TN";"🟣 ANTO(TN)";""),IF(Calendario!F21="TT";"🟠 ANTO(TT)";""),IF(Calendario!G21="";"🟢 ELIAS";""),IF(Calendario!G21="CL";"🟤 ELIAS(CL)";""),IF(Calendario!G21="FV";"🟡 ELIAS(FV)";""),IF(Calendario!G21="TM";"🔵 ELIAS(TM)";""),IF(Calendario!G21="TN";"🟣 ELIAS(TN)";""),IF(Calendario!G21="TT";"🟠 ELIAS(TT)";""),IF(Calendario!H21="";"🟢 CRIS";""),IF(Calendario!H21="CL";"🟤 CRIS(CL)";""),IF(Calendario!H21="FV";"🟡 CRIS(FV)";""),IF(Calendario!H21="TM";"🔵 CRIS(TM)";""),IF(Calendario!H21="TN";"🟣 CRIS(TN)";""),IF(Calendario!H21="TT";"🟠 CRIS(TT)";""))
