Workbook

Sheet Calendario
A1: Fecha | B1: Dia | C1: RESI | D1: OSCAR | E1: CLARA | F1: ANNA | G1: PEPE | H1: IVAN | I1: YERAY
A2: JULIO 2026
A3: 46204 | B3: Mie
A4: 46205 | B4: Jue
A5: 46206 | B5: Vie
A6: 46207 | B6: Sab
A7: 46208 | B7: Dom
A8: 46209 | B8: Lun
A9: 46210 | B9: Mar
A10: 46211 | B10: Mie
A11: 46212 | B11: Jue
A12: 46213 | B12: Vie
A13: 46214 | B13: Sab
A14: 46215 | B14: Dom
... A33: 46234 | B33: Vie
A34: AGOSTO 2026
A35: 46235 | B35: Sab
A36: 46236 | B36: Dom
A37: 46237 | B37: Lun
A38: 46238 | B38: Mar
A39: 46239 | B39: Mie
A40: 46240 | B40: Jue
A41: 46241 | B41: Vie
A42: 46242 | B42: Sab
A43: 46243 | B43: Dom
A44: 46244 | B44: Lun
A45: 46245 | B45: Mar
A46: 46246 | B46: Mie
... A65: 46265 | B65: Lun
A68: LEYENDA
B69: TM -> Trabajar manana (~08-15)
B70: TT -> Trabajar tarde (~15-21)
B71: TN -> Trabajar noche (~21-08)
B72: FV -> Fuera (puedo volver)
B73: FN -> Fuera (NO volver)
B74: OC -> Ocupado
B75: RE -> Recuperaciones
B76: OT -> Otros
B77: CL -> Clases
B78: (vacio = disponible)

Sheet Resumen
A1: PANEL DE DISPONIBILIDAD — JULIO & AGOSTO 2026
B2: TOTAL DIAS | C2: 62 | E2: TODOS LIBRES | F2: =COUNTIF(J6:J67,"SI") | H2: MAX 1 OCUPADO | I2: =COUNTIF(K6:K67,"SI") | K2: MAX 2 OCUPADOS | L2: =COUNTIF(L6:L67,"SI") | N2: MAX 3 OCUPADOS | O2: =COUNTIF(M6:M67,"SI")
A4: Fecha | B4: Dia | C4: Libres | D4: TM | E4: TT | F4: TN | G4: FV | H4: FN | I4: Ocupados (TM+TT+TN) | J4: Todos libres | K4: Todos -1 | L4: Todos -2 | M4: Todos -3 | N4: Todos FN | O4: % Disponible
J5: Umbrales: minimo de personas libres
A6: 46204 | B6: Mie | C6: =COUNTIF(Calendario!C3:I3,"") | D6: =COUNTIF(Calendario!C3:I3,"TM") | E6: =COUNTIF(Calendario!C3:I3,"TT") | F6: =COUNTIF(Calendario!C3:I3,"TN") | G6: =COUNTIF(Calendario!C3:I3,"FV") | H6: =COUNTIF(Calendario!C3:I3,"FN") | I6: =D6+E6+F6 | J6: =IF(C6>=7,"SI","") | K6: =IF(C6>=6,"SI","") | L6: =IF(C6>=5,"SI","") | M6: =IF(C6>=4,"SI","") | N6: =IF(H6=7,"SI","") | O6: =C6/7
A7: 46205 | B7: Jue | C7: =COUNTIF(Calendario!C4:I4,"") | D7: =COUNTIF(Calendario!C4:I4,"TM") | E7: =COUNTIF(Calendario!C4:I4,"TT") | F7: =COUNTIF(Calendario!C4:I4,"TN") | G7: =COUNTIF(Calendario!C4:I4,"FV") | H7: =COUNTIF(Calendario!C4:I4,"FN") | I7: =D7+E7+F7 | J7: =IF(C7>=7,"SI","") | K7: =IF(C7>=6,"SI","") | L7: =IF(C7>=5,"SI","") | M7: =IF(C7>=4,"SI","") | N7: =IF(H7=7,"SI","") | O7: =C7/7
A8: 46206 | B8: Vie | C8: =COUNTIF(Calendario!C5:I5,"") | D8: =COUNTIF(Calendario!C5:I5,"TM") | E8: =COUNTIF(Calendario!C5:I5,"TT") | F8: =COUNTIF(Calendario!C5:I5,"TN") | G8: =COUNTIF(Calendario!C5:I5,"FV") | H8: =COUNTIF(Calendario!C5:I5,"FN") | I8: =D8+E8+F8 | J8: =IF(C8>=7,"SI","") | K8: =IF(C8>=6,"SI","") | L8: =IF(C8>=5,"SI","") | M8: =IF(C8>=4,"SI","") | N8: =IF(H8=7,"SI","") | O8: =C8/7
A9: 46207 | B9: Sab | C9: =COUNTIF(Calendario!C6:I6,"") | D9: =COUNTIF(Calendario!C6:I6,"TM") | E9: =COUNTIF(Calendario!C6:I6,"TT") | F9: =COUNTIF(Calendario!C6:I6,"TN") | G9: =COUNTIF(Calendario!C6:I6,"FV") | H9: =COUNTIF(Calendario!C6:I6,"FN") | I9: =D9+E9+F9 | J9: =IF(C9>=7,"SI","") | K9: =IF(C9>=6,"SI","") | L9: =IF(C9>=5,"SI","") | M9: =IF(C9>=4,"SI","") | N9: =IF(H9=7,"SI","") | O9: =C9/7
A10: 46208 | B10: Dom | C10: =COUNTIF(Calendario!C7:I7,"") | D10: =COUNTIF(Calendario!C7:I7,"TM") | E10: =COUNTIF(Calendario!C7:I7,"TT") | F10: =COUNTIF(Calendario!C7:I7,"TN") | G10: =COUNTIF(Calendario!C7:I7,"FV") | H10: =COUNTIF(Calendario!C7:I7,"FN") | I10: =D10+E10+F10 | J10: =IF(C10>=7,"SI","") | K10: =IF(C10>=6,"SI","") | L10: =IF(C10>=5,"SI","") | M10: =IF(C10>=4,"SI","") | N10: =IF(H10=7,"SI","") | O10: =C10/7
A11: 46209 | B11: Lun | C11: =COUNTIF(Calendario!C8:I8,"") | D11: =COUNTIF(Calendario!C8:I8,"TM") | E11: =COUNTIF(Calendario!C8:I8,"TT") | F11: =COUNTIF(Calendario!C8:I8,"TN") | G11: =COUNTIF(Calendario!C8:I8,"FV") | H11: =COUNTIF(Calendario!C8:I8,"FN") | I11: =D11+E11+F11 | J11: =IF(C11>=7,"SI","") | K11: =IF(C11>=6,"SI","") | L11: =IF(C11>=5,"SI","") | M11: =IF(C11>=4,"SI","") | N11: =IF(H11=7,"SI","") | O11: =C11/7
A12: 46210 | B12: Mar | C12: =COUNTIF(Calendario!C9:I9,"") | D12: =COUNTIF(Calendario!C9:I9,"TM") | E12: =COUNTIF(Calendario!C9:I9,"TT") | F12: =COUNTIF(Calendario!C9:I9,"TN") | G12: =COUNTIF(Calendario!C9:I9,"FV") | H12: =COUNTIF(Calendario!C9:I9,"FN") | I12: =D12+E12+F12 | J12: =IF(C12>=7,"SI","") | K12: =IF(C12>=6,"SI","") | L12: =IF(C12>=5,"SI","") | M12: =IF(C12>=4,"SI","") | N12: =IF(H12=7,"SI","") | O12: =C12/7
A13: 46211 | B13: Mie | C13: =COUNTIF(Calendario!C10:I10,"") | D13: =COUNTIF(Calendario!C10:I10,"TM") | E13: =COUNTIF(Calendario!C10:I10,"TT") | F13: =COUNTIF(Calendario!C10:I10,"TN") | G13: =COUNTIF(Calendario!C10:I10,"FV") | H13: =COUNTIF(Calendario!C10:I10,"FN") | I13: =D13+E13+F13 | J13: =IF(C13>=7,"SI","") | K13: =IF(C13>=6,"SI","") | L13: =IF(C13>=5,"SI","") | M13: =IF(C13>=4,"SI","") | N13: =IF(H13=7,"SI","") | O13: =C13/7
A14: 46212 | B14: Jue | C14: =COUNTIF(Calendario!C11:I11,"") | D14: =COUNTIF(Calendario!C11:I11,"TM") | E14: =COUNTIF(Calendario!C11:I11,"TT") | F14: =COUNTIF(Calendario!C11:I11,"TN") | G14: =COUNTIF(Calendario!C11:I11,"FV") | H14: =COUNTIF(Calendario!C11:I11,"FN") | I14: =D14+E14+F14 | J14: =IF(C14>=7,"SI","") | K14: =IF(C14>=6,"SI","") | L14: =IF(C14>=5,"SI","") | M14: =IF(C14>=4,"SI","") | N14: =IF(H14=7,"SI","") | O14: =C14/7
A15: 46213 | B15: Vie | C15: =COUNTIF(Calendario!C12:I12,"") | D15: =COUNTIF(Calendario!C12:I12,"TM") | E15: =COUNTIF(Calendario!C12:I12,"TT") | F15: =COUNTIF(Calendario!C12:I12,"TN") | G15: =COUNTIF(Calendario!C12:I12,"FV") | H15: =COUNTIF(Calendario!C12:I12,"FN") | I15: =D15+E15+F15 | J15: =IF(C15>=7,"SI","") | K15: =IF(C15>=6,"SI","") | L15: =IF(C15>=5,"SI","") | M15: =IF(C15>=4,"SI","") | N15: =IF(H15=7,"SI","") | O15: =C15/7
A16: 46214 | B16: Sab | C16: =COUNTIF(Calendario!C13:I13,"") | D16: =COUNTIF(Calendario!C13:I13,"TM") | E16: =COUNTIF(Calendario!C13:I13,"TT") | F16: =COUNTIF(Calendario!C13:I13,"TN") | G16: =COUNTIF(Calendario!C13:I13,"FV") | H16: =COUNTIF(Calendario!C13:I13,"FN") | I16: =D16+E16+F16 | J16: =IF(C16>=7,"SI","") | K16: =IF(C16>=6,"SI","") | L16: =IF(C16>=5,"SI","") | M16: =IF(C16>=4,"SI","") | N16: =IF(H16=7,"SI","") | O16: =C16/7
A17: 46215 | B17: Dom | C17: =COUNTIF(Calendario!C14:I14,"") | D17: =COUNTIF(Calendario!C14:I14,"TM") | E17: =COUNTIF(Calendario!C14:I14,"TT") | F17: =COUNTIF(Calendario!C14:I14,"TN") | G17: =COUNTIF(Calendario!C14:I14,"FV") | H17: =COUNTIF(Calendario!C14:I14,"FN") | I17: =D17+E17+F17 | J17: =IF(C17>=7,"SI","") | K17: =IF(C17>=6,"SI","") | L17: =IF(C17>=5,"SI","") | M17: =IF(C17>=4,"SI","") | N17: =IF(H17=7,"SI","") | O17: =C17/7
... A36: 46234 | B36: Vie | C36: =COUNTIF(Calendario!C33:I33,"") | D36: =COUNTIF(Calendario!C33:I33,"TM") | E36: =COUNTIF(Calendario!C33:I33,"TT") | F36: =COUNTIF(Calendario!C33:I33,"TN") | G36: =COUNTIF(Calendario!C33:I33,"FV") | H36: =COUNTIF(Calendario!C33:I33,"FN") | I36: =D36+E36+F36 | J36: =IF(C36>=7,"SI","") | K36: =IF(C36>=6,"SI","") | L36: =IF(C36>=5,"SI","") | M36: =IF(C36>=4,"SI","") | N36: =IF(H36=7,"SI","") | O36: =C36/7
A37: 46235 | B37: Sab | C37: =COUNTIF(Calendario!C35:I35,"") | D37: =COUNTIF(Calendario!C35:I35,"TM") | E37: =COUNTIF(Calendario!C35:I35,"TT") | F37: =COUNTIF(Calendario!C35:I35,"TN") | G37: =COUNTIF(Calendario!C35:I35,"FV") | H37: =COUNTIF(Calendario!C35:I35,"FN") | I37: =D37+E37+F37 | J37: =IF(C37>=7,"SI","") | K37: =IF(C37>=6,"SI","") | L37: =IF(C37>=5,"SI","") | M37: =IF(C37>=4,"SI","") | N37: =IF(H37=7,"SI","") | O37: =C37/7
A38: 46236 | B38: Dom | C38: =COUNTIF(Calendario!C36:I36,"") | D38: =COUNTIF(Calendario!C36:I36,"TM") | E38: =COUNTIF(Calendario!C36:I36,"TT") | F38: =COUNTIF(Calendario!C36:I36,"TN") | G38: =COUNTIF(Calendario!C36:I36,"FV") | H38: =COUNTIF(Calendario!C36:I36,"FN") | I38: =D38+E38+F38 | J38: =IF(C38>=7,"SI","") | K38: =IF(C38>=6,"SI","") | L38: =IF(C38>=5,"SI","") | M38: =IF(C38>=4,"SI","") | N38: =IF(H38=7,"SI","") | O38: =C38/7
A39: 46237 | B39: Lun | C39: =COUNTIF(Calendario!C37:I37,"") | D39: =COUNTIF(Calendario!C37:I37,"TM") | E39: =COUNTIF(Calendario!C37:I37,"TT") | F39: =COUNTIF(Calendario!C37:I37,"TN") | G39: =COUNTIF(Calendario!C37:I37,"FV") | H39: =COUNTIF(Calendario!C37:I37,"FN") | I39: =D39+E39+F39 | J39: =IF(C39>=7,"SI","") | K39: =IF(C39>=6,"SI","") | L39: =IF(C39>=5,"SI","") | M39: =IF(C39>=4,"SI","") | N39: =IF(H39=7,"SI","") | O39: =C39/7
A40: 46238 | B40: Mar | C40: =COUNTIF(Calendario!C38:I38,"") | D40: =COUNTIF(Calendario!C38:I38,"TM") | E40: =COUNTIF(Calendario!C38:I38,"TT") | F40: =COUNTIF(Calendario!C38:I38,"TN") | G40: =COUNTIF(Calendario!C38:I38,"FV") | H40: =COUNTIF(Calendario!C38:I38,"FN") | I40: =D40+E40+F40 | J40: =IF(C40>=7,"SI","") | K40: =IF(C40>=6,"SI","") | L40: =IF(C40>=5,"SI","") | M40: =IF(C40>=4,"SI","") | N40: =IF(H40=7,"SI","") | O40: =C40/7
A41: 46239 | B41: Mie | C41: =COUNTIF(Calendario!C39:I39,"") | D41: =COUNTIF(Calendario!C39:I39,"TM") | E41: =COUNTIF(Calendario!C39:I39,"TT") | F41: =COUNTIF(Calendario!C39:I39,"TN") | G41: =COUNTIF(Calendario!C39:I39,"FV") | H41: =COUNTIF(Calendario!C39:I39,"FN") | I41: =D41+E41+F41 | J41: =IF(C41>=7,"SI","") | K41: =IF(C41>=6,"SI","") | L41: =IF(C41>=5,"SI","") | M41: =IF(C41>=4,"SI","") | N41: =IF(H41=7,"SI","") | O41: =C41/7
A42: 46240 | B42: Jue | C42: =COUNTIF(Calendario!C40:I40,"") | D42: =COUNTIF(Calendario!C40:I40,"TM") | E42: =COUNTIF(Calendario!C40:I40,"TT") | F42: =COUNTIF(Calendario!C40:I40,"TN") | G42: =COUNTIF(Calendario!C40:I40,"FV") | H42: =COUNTIF(Calendario!C40:I40,"FN") | I42: =D42+E42+F42 | J42: =IF(C42>=7,"SI","") | K42: =IF(C42>=6,"SI","") | L42: =IF(C42>=5,"SI","") | M42: =IF(C42>=4,"SI","") | N42: =IF(H42=7,"SI","") | O42: =C42/7
A43: 46241 | B43: Vie | C43: =COUNTIF(Calendario!C41:I41,"") | D43: =COUNTIF(Calendario!C41:I41,"TM") | E43: =COUNTIF(Calendario!C41:I41,"TT") | F43: =COUNTIF(Calendario!C41:I41,"TN") | G43: =COUNTIF(Calendario!C41:I41,"FV") | H43: =COUNTIF(Calendario!C41:I41,"FN") | I43: =D43+E43+F43 | J43: =IF(C43>=7,"SI","") | K43: =IF(C43>=6,"SI","") | L43: =IF(C43>=5,"SI","") | M43: =IF(C43>=4,"SI","") | N43: =IF(H43=7,"SI","") | O43: =C43/7
A44: 46242 | B44: Sab | C44: =COUNTIF(Calendario!C42:I42,"") | D44: =COUNTIF(Calendario!C42:I42,"TM") | E44: =COUNTIF(Calendario!C42:I42,"TT") | F44: =COUNTIF(Calendario!C42:I42,"TN") | G44: =COUNTIF(Calendario!C42:I42,"FV") | H44: =COUNTIF(Calendario!C42:I42,"FN") | I44: =D44+E44+F44 | J44: =IF(C44>=7,"SI","") | K44: =IF(C44>=6,"SI","") | L44: =IF(C44>=5,"SI","") | M44: =IF(C44>=4,"SI","") | N44: =IF(H44=7,"SI","") | O44: =C44/7
A45: 46243 | B45: Dom | C45: =COUNTIF(Calendario!C43:I43,"") | D45: =COUNTIF(Calendario!C43:I43,"TM") | E45: =COUNTIF(Calendario!C43:I43,"TT") | F45: =COUNTIF(Calendario!C43:I43,"TN") | G45: =COUNTIF(Calendario!C43:I43,"FV") | H45: =COUNTIF(Calendario!C43:I43,"FN") | I45: =D45+E45+F45 | J45: =IF(C45>=7,"SI","") | K45: =IF(C45>=6,"SI","") | L45: =IF(C45>=5,"SI","") | M45: =IF(C45>=4,"SI","") | N45: =IF(H45=7,"SI","") | O45: =C45/7
A46: 46244 | B46: Lun | C46: =COUNTIF(Calendario!C44:I44,"") | D46: =COUNTIF(Calendario!C44:I44,"TM") | E46: =COUNTIF(Calendario!C44:I44,"TT") | F46: =COUNTIF(Calendario!C44:I44,"TN") | G46: =COUNTIF(Calendario!C44:I44,"FV") | H46: =COUNTIF(Calendario!C44:I44,"FN") | I46: =D46+E46+F46 | J46: =IF(C46>=7,"SI","") | K46: =IF(C46>=6,"SI","") | L46: =IF(C46>=5,"SI","") | M46: =IF(C46>=4,"SI","") | N46: =IF(H46=7,"SI","") | O46: =C46/7
A47: 46245 | B47: Mar | C47: =COUNTIF(Calendario!C45:I45,"") | D47: =COUNTIF(Calendario!C45:I45,"TM") | E47: =COUNTIF(Calendario!C45:I45,"TT") | F47: =COUNTIF(Calendario!C45:I45,"TN") | G47: =COUNTIF(Calendario!C45:I45,"FV") | H47: =COUNTIF(Calendario!C45:I45,"FN") | I47: =D47+E47+F47 | J47: =IF(C47>=7,"SI","") | K47: =IF(C47>=6,"SI","") | L47: =IF(C47>=5,"SI","") | M47: =IF(C47>=4,"SI","") | N47: =IF(H47=7,"SI","") | O47: =C47/7
A48: 46246 | B48: Mie | C48: =COUNTIF(Calendario!C46:I46,"") | D48: =COUNTIF(Calendario!C46:I46,"TM") | E48: =COUNTIF(Calendario!C46:I46,"TT") | F48: =COUNTIF(Calendario!C46:I46,"TN") | G48: =COUNTIF(Calendario!C46:I46,"FV") | H48: =COUNTIF(Calendario!C46:I46,"FN") | I48: =D48+E48+F48 | J48: =IF(C48>=7,"SI","") | K48: =IF(C48>=6,"SI","") | L48: =IF(C48>=5,"SI","") | M48: =IF(C48>=4,"SI","") | N48: =IF(H48=7,"SI","") | O48: =C48/7
... A67: 46265 | B67: Lun | C67: =COUNTIF(Calendario!C65:I65,"") | D67: =COUNTIF(Calendario!C65:I65,"TM") | E67: =COUNTIF(Calendario!C65:I65,"TT") | F67: =COUNTIF(Calendario!C65:I65,"TN") | G67: =COUNTIF(Calendario!C65:I65,"FV") | H67: =COUNTIF(Calendario!C65:I65,"FN") | I67: =D67+E67+F67 | J67: =IF(C67>=7,"SI","") | K67: =IF(C67>=6,"SI","") | L67: =IF(C67>=5,"SI","") | M67: =IF(C67>=4,"SI","") | N67: =IF(H67=7,"SI","") | O67: =C67/7
A68: TOTALES | C68: =SUM(C6:C67) | D68: =SUM(D6:D67) | E68: =SUM(E6:E67) | F68: =SUM(F6:F67) | G68: =SUM(G6:G67) | H68: =SUM(H6:H67) | I68: =SUM(I6:I67) | J68: =SUM(J6:J67) | ... N68: =SUM(N6:N67) | O68: =AVERAGE(O6:O67)

Sheet Julio
A1: JULIO 2026 — Quien puede cada dia
A2: 1 | B2: 46204 | C2: Mie | D2: =TEXTJOIN(", ";TRUE,IF(Calendario!C3="","RESI",""), IF(Calendario!D3="","OSCAR",""), IF(Calendario!E3="","CLARA",""), IF(Calendario!F3="","ANNA",""), IF(Calendario!G3="","PEPE",""), IF(Calendario!H3="","IVAN",""), IF(Calendario!I3="","YERAY","")) | E2: =TEXTJOIN(", ";TRUE,IF(Calendario!C3<>"","RESI("&Calendario!C3&")",""), IF(Calendario!D3<>"","OSCAR("&Calendario!D3&")",""), IF(Calendario!E3<>"","CLARA("&Calendario!E3&")",""), IF(Calendario!F3<>"","ANNA("&Calendario!F3&")",""), IF(Calendario!G3<>"","PEPE("&Calendario!G3&")",""), IF(Calendario!H3<>"","IVAN("&Calendario!H3&")",""), IF(Calendario!I3<>"","YERAY("&Calendario!I3&")",""))
A3: 2 | B3: 46205 | C3: Jue | D3: =TEXTJOIN(", ";TRUE,IF(Calendario!C4="","RESI",""), IF(Calendario!D4="","OSCAR",""), IF(Calendario!E4="","CLARA",""), IF(Calendario!F4="","ANNA",""), IF(Calendario!G4="","PEPE",""), IF(Calendario!H4="","IVAN",""), IF(Calendario!I4="","YERAY","")) | E3: =TEXTJOIN(", ";TRUE,IF(Calendario!C4<>"","RESI("&Calendario!C4&")",""), IF(Calendario!D4<>"","OSCAR("&Calendario!D4&")",""), IF(Calendario!E4<>"","CLARA("&Calendario!E4&")",""), IF(Calendario!F4<>"","ANNA("&Calendario!F4&")",""), IF(Calendario!G4<>"","PEPE("&Calendario!G4&")",""), IF(Calendario!H4<>"","IVAN("&Calendario!H4&")",""), IF(Calendario!I4<>"","YERAY("&Calendario!I4&")",""))
A4: 3 | B4: 46206 | C4: Vie | D4: =TEXTJOIN(", ";TRUE,IF(Calendario!C5="","RESI",""), IF(Calendario!D5="","OSCAR",""), IF(Calendario!E5="","CLARA",""), IF(Calendario!F5="","ANNA",""), IF(Calendario!G5="","PEPE",""), IF(Calendario!H5="","IVAN",""), IF(Calendario!I5="","YERAY","")) | E4: =TEXTJOIN(", ";TRUE,IF(Calendario!C5<>"","RESI("&Calendario!C5&")",""), IF(Calendario!D5<>"","OSCAR("&Calendario!D5&")",""), IF(Calendario!E5<>"","CLARA("&Calendario!E5&")",""), IF(Calendario!F5<>"","ANNA("&Calendario!F5&")",""), IF(Calendario!G5<>"","PEPE("&Calendario!G5&")",""), IF(Calendario!H5<>"","IVAN("&Calendario!H5&")",""), IF(Calendario!I5<>"","YERAY("&Calendario!I5&")",""))
A5: 4 | B5: 46207 | C5: Sab | D5: =TEXTJOIN(", ";TRUE,IF(Calendario!C6="","RESI",""), IF(Calendario!D6="","OSCAR",""), IF(Calendario!E6="","CLARA",""), IF(Calendario!F6="","ANNA",""), IF(Calendario!G6="","PEPE",""), IF(Calendario!H6="","IVAN",""), IF(Calendario!I6="","YERAY","")) | E5: =TEXTJOIN(", ";TRUE,IF(Calendario!C6<>"","RESI("&Calendario!C6&")",""), IF(Calendario!D6<>"","OSCAR("&Calendario!D6&")",""), IF(Calendario!E6<>"","CLARA("&Calendario!E6&")",""), IF(Calendario!F6<>"","ANNA("&Calendario!F6&")",""), IF(Calendario!G6<>"","PEPE("&Calendario!G6&")",""), IF(Calendario!H6<>"","IVAN("&Calendario!H6&")",""), IF(Calendario!I6<>"","YERAY("&Calendario!I6&")",""))
A6: 5 | B6: 46208 | C6: Dom | D6: =TEXTJOIN(", ";TRUE,IF(Calendario!C7="","RESI",""), IF(Calendario!D7="","OSCAR",""), IF(Calendario!E7="","CLARA",""), IF(Calendario!F7="","ANNA",""), IF(Calendario!G7="","PEPE",""), IF(Calendario!H7="","IVAN",""), IF(Calendario!I7="","YERAY","")) | E6: =TEXTJOIN(", ";TRUE,IF(Calendario!C7<>"","RESI("&Calendario!C7&")",""), IF(Calendario!D7<>"","OSCAR("&Calendario!D7&")",""), IF(Calendario!E7<>"","CLARA("&Calendario!E7&")",""), IF(Calendario!F7<>"","ANNA("&Calendario!F7&")",""), IF(Calendario!G7<>"","PEPE("&Calendario!G7&")",""), IF(Calendario!H7<>"","IVAN("&Calendario!H7&")",""), IF(Calendario!I7<>"","YERAY("&Calendario!I7&")",""))
A7: 6 | B7: 46209 | C7: Lun | D7: =TEXTJOIN(", ";TRUE,IF(Calendario!C8="","RESI",""), IF(Calendario!D8="","OSCAR",""), IF(Calendario!E8="","CLARA",""), IF(Calendario!F8="","ANNA",""), IF(Calendario!G8="","PEPE",""), IF(Calendario!H8="","IVAN",""), IF(Calendario!I8="","YERAY","")) | E7: =TEXTJOIN(", ";TRUE,IF(Calendario!C8<>"","RESI("&Calendario!C8&")",""), IF(Calendario!D8<>"","OSCAR("&Calendario!D8&")",""), IF(Calendario!E8<>"","CLARA("&Calendario!E8&")",""), IF(Calendario!F8<>"","ANNA("&Calendario!F8&")",""), IF(Calendario!G8<>"","PEPE("&Calendario!G8&")",""), IF(Calendario!H8<>"","IVAN("&Calendario!H8&")",""), IF(Calendario!I8<>"","YERAY("&Calendario!I8&")",""))
A8: 7 | B8: 46210 | C8: Mar | D8: =TEXTJOIN(", ";TRUE,IF(Calendario!C9="","RESI",""), IF(Calendario!D9="","OSCAR",""), IF(Calendario!E9="","CLARA",""), IF(Calendario!F9="","ANNA",""), IF(Calendario!G9="","PEPE",""), IF(Calendario!H9="","IVAN",""), IF(Calendario!I9="","YERAY","")) | E8: =TEXTJOIN(", ";TRUE,IF(Calendario!C9<>"","RESI("&Calendario!C9&")",""), IF(Calendario!D9<>"","OSCAR("&Calendario!D9&")",""), IF(Calendario!E9<>"","CLARA("&Calendario!E9&")",""), IF(Calendario!F9<>"","ANNA("&Calendario!F9&")",""), IF(Calendario!G9<>"","PEPE("&Calendario!G9&")",""), IF(Calendario!H9<>"","IVAN("&Calendario!H9&")",""), IF(Calendario!I9<>"","YERAY("&Calendario!I9&")",""))
A9: 8 | B9: 46211 | C9: Mie | D9: =TEXTJOIN(", ";TRUE,IF(Calendario!C10="","RESI",""), IF(Calendario!D10="","OSCAR",""), IF(Calendario!E10="","CLARA",""), IF(Calendario!F10="","ANNA",""), IF(Calendario!G10="","PEPE",""), IF(Calendario!H10="","IVAN",""), IF(Calendario!I10="","YERAY","")) | E9: =TEXTJOIN(", ";TRUE,IF(Calendario!C10<>"","RESI("&Calendario!C10&")",""), IF(Calendario!D10<>"","OSCAR("&Calendario!D10&")",""), IF(Calendario!E10<>"","CLARA("&Calendario!E10&")",""), IF(Calendario!F10<>"","ANNA("&Calendario!F10&")",""), IF(Calendario!G10<>"","PEPE("&Calendario!G10&")",""), IF(Calendario!H10<>"","IVAN("&Calendario!H10&")",""), IF(Calendario!I10<>"","YERAY("&Calendario!I10&")",""))
A10: 9 | B10: 46212 | C10: Jue | D10: =TEXTJOIN(", ";TRUE,IF(Calendario!C11="","RESI",""), IF(Calendario!D11="","OSCAR",""), IF(Calendario!E11="","CLARA",""), IF(Calendario!F11="","ANNA",""), IF(Calendario!G11="","PEPE",""), IF(Calendario!H11="","IVAN",""), IF(Calendario!I11="","YERAY","")) | E10: =TEXTJOIN(", ";TRUE,IF(Calendario!C11<>"","RESI("&Calendario!C11&")",""), IF(Calendario!D11<>"","OSCAR("&Calendario!D11&")",""), IF(Calendario!E11<>"","CLARA("&Calendario!E11&")",""), IF(Calendario!F11<>"","ANNA("&Calendario!F11&")",""), IF(Calendario!G11<>"","PEPE("&Calendario!G11&")",""), IF(Calendario!H11<>"","IVAN("&Calendario!H11&")",""), IF(Calendario!I11<>"","YERAY("&Calendario!I11&")",""))
A11: 10 | B11: 46213 | C11: Vie | D11: =TEXTJOIN(", ";TRUE,IF(Calendario!C12="","RESI",""), IF(Calendario!D12="","OSCAR",""), IF(Calendario!E12="","CLARA",""), IF(Calendario!F12="","ANNA",""), IF(Calendario!G12="","PEPE",""), IF(Calendario!H12="","IVAN",""), IF(Calendario!I12="","YERAY","")) | E11: =TEXTJOIN(", ";TRUE,IF(Calendario!C12<>"","RESI("&Calendario!C12&")",""), IF(Calendario!D12<>"","OSCAR("&Calendario!D12&")",""), IF(Calendario!E12<>"","CLARA("&Calendario!E12&")",""), IF(Calendario!F12<>"","ANNA("&Calendario!F12&")",""), IF(Calendario!G12<>"","PEPE("&Calendario!G12&")",""), IF(Calendario!H12<>"","IVAN("&Calendario!H12&")",""), IF(Calendario!I12<>"","YERAY("&Calendario!I12&")",""))
A12: 11 | B12: 46214 | C12: Sab | D12: =TEXTJOIN(", ";TRUE,IF(Calendario!C13="","RESI",""), IF(Calendario!D13="","OSCAR",""), IF(Calendario!E13="","CLARA",""), IF(Calendario!F13="","ANNA",""), IF(Calendario!G13="","PEPE",""), IF(Calendario!H13="","IVAN",""), IF(Calendario!I13="","YERAY","")) | E12: =TEXTJOIN(", ";TRUE,IF(Calendario!C13<>"","RESI("&Calendario!C13&")",""), IF(Calendario!D13<>"","OSCAR("&Calendario!D13&")",""), IF(Calendario!E13<>"","CLARA("&Calendario!E13&")",""), IF(Calendario!F13<>"","ANNA("&Calendario!F13&")",""), IF(Calendario!G13<>"","PEPE("&Calendario!G13&")",""), IF(Calendario!H13<>"","IVAN("&Calendario!H13&")",""), IF(Calendario!I13<>"","YERAY("&Calendario!I13&")",""))
A13: 12 | B13: 46215 | C13: Dom | D13: =TEXTJOIN(", ";TRUE,IF(Calendario!C14="","RESI",""), IF(Calendario!D14="","OSCAR",""), IF(Calendario!E14="","CLARA",""), IF(Calendario!F14="","ANNA",""), IF(Calendario!G14="","PEPE",""), IF(Calendario!H14="","IVAN",""), IF(Calendario!I14="","YERAY","")) | E13: =TEXTJOIN(", ";TRUE,IF(Calendario!C14<>"","RESI("&Calendario!C14&")",""), IF(Calendario!D14<>"","OSCAR("&Calendario!D14&")",""), IF(Calendario!E14<>"","CLARA("&Calendario!E14&")",""), IF(Calendario!F14<>"","ANNA("&Calendario!F14&")",""), IF(Calendario!G14<>"","PEPE("&Calendario!G14&")",""), IF(Calendario!H14<>"","IVAN("&Calendario!H14&")",""), IF(Calendario!I14<>"","YERAY("&Calendario!I14&")",""))
... A32: 31 | B32: 46234 | C32: Vie | D32: =TEXTJOIN(", ";TRUE,IF(Calendario!C33="","RESI",""), IF(Calendario!D33="","OSCAR",""), IF(Calendario!E33="","CLARA",""), IF(Calendario!F33="","ANNA",""), IF(Calendario!G33="","PEPE",""), IF(Calendario!H33="","IVAN",""), IF(Calendario!I33="","YERAY","")) | E32: =TEXTJOIN(", ";TRUE,IF(Calendario!C33<>"","RESI("&Calendario!C33&")",""), IF(Calendario!D33<>"","OSCAR("&Calendario!D33&")",""), IF(Calendario!E33<>"","CLARA("&Calendario!E33&")",""), IF(Calendario!F33<>"","ANNA("&Calendario!F33&")",""), IF(Calendario!G33<>"","PEPE("&Calendario!G33&")",""), IF(Calendario!H33<>"","IVAN("&Calendario!H33&")",""), IF(Calendario!I33<>"","YERAY("&Calendario!I33&")",""))

Sheet Agosto
A1: AGOSTO 2026 — Quien puede cada dia
A2: 1 | B2: 46235 | C2: Sab | D2: =TEXTJOIN(", ";TRUE,IF(Calendario!C35="","RESI",""), IF(Calendario!D35="","OSCAR",""), IF(Calendario!E35="","CLARA",""), IF(Calendario!F35="","ANNA",""), IF(Calendario!G35="","PEPE",""), IF(Calendario!H35="","IVAN",""), IF(Calendario!I35="","YERAY","")) | E2: =TEXTJOIN(", ";TRUE,IF(Calendario!C35<>"","RESI("&Calendario!C35&")",""), IF(Calendario!D35<>"","OSCAR("&Calendario!D35&")",""), IF(Calendario!E35<>"","CLARA("&Calendario!E35&")",""), IF(Calendario!F35<>"","ANNA("&Calendario!F35&")",""), IF(Calendario!G35<>"","PEPE("&Calendario!G35&")",""), IF(Calendario!H35<>"","IVAN("&Calendario!H35&")",""), IF(Calendario!I35<>"","YERAY("&Calendario!I35&")",""))
A3: 2 | B3: 46236 | C3: Dom | D3: =TEXTJOIN(", ";TRUE,IF(Calendario!C36="","RESI",""), IF(Calendario!D36="","OSCAR",""), IF(Calendario!E36="","CLARA",""), IF(Calendario!F36="","ANNA",""), IF(Calendario!G36="","PEPE",""), IF(Calendario!H36="","IVAN",""), IF(Calendario!I36="","YERAY","")) | E3: =TEXTJOIN(", ";TRUE,IF(Calendario!C36<>"","RESI("&Calendario!C36&")",""), IF(Calendario!D36<>"","OSCAR("&Calendario!D36&")",""), IF(Calendario!E36<>"","CLARA("&Calendario!E36&")",""), IF(Calendario!F36<>"","ANNA("&Calendario!F36&")",""), IF(Calendario!G36<>"","PEPE("&Calendario!G36&")",""), IF(Calendario!H36<>"","IVAN("&Calendario!H36&")",""), IF(Calendario!I36<>"","YERAY("&Calendario!I36&")",""))
A4: 3 | B4: 46237 | C4: Lun | D4: =TEXTJOIN(", ";TRUE,IF(Calendario!C37="","RESI",""), IF(Calendario!D37="","OSCAR",""), IF(Calendario!E37="","CLARA",""), IF(Calendario!F37="","ANNA",""), IF(Calendario!G37="","PEPE",""), IF(Calendario!H37="","IVAN",""), IF(Calendario!I37="","YERAY","")) | E4: =TEXTJOIN(", ";TRUE,IF(Calendario!C37<>"","RESI("&Calendario!C37&")",""), IF(Calendario!D37<>"","OSCAR("&Calendario!D37&")",""), IF(Calendario!E37<>"","CLARA("&Calendario!E37&")",""), IF(Calendario!F37<>"","ANNA("&Calendario!F37&")",""), IF(Calendario!G37<>"","PEPE("&Calendario!G37&")",""), IF(Calendario!H37<>"","IVAN("&Calendario!H37&")",""), IF(Calendario!I37<>"","YERAY("&Calendario!I37&")",""))
A5: 4 | B5: 46238 | C5: Mar | D5: =TEXTJOIN(", ";TRUE,IF(Calendario!C38="","RESI",""), IF(Calendario!D38="","OSCAR",""), IF(Calendario!E38="","CLARA",""), IF(Calendario!F38="","ANNA",""), IF(Calendario!G38="","PEPE",""), IF(Calendario!H38="","IVAN",""), IF(Calendario!I38="","YERAY","")) | E5: =TEXTJOIN(", ";TRUE,IF(Calendario!C38<>"","RESI("&Calendario!C38&")",""), IF(Calendario!D38<>"","OSCAR("&Calendario!D38&")",""), IF(Calendario!E38<>"","CLARA("&Calendario!E38&")",""), IF(Calendario!F38<>"","ANNA("&Calendario!F38&")",""), IF(Calendario!G38<>"","PEPE("&Calendario!G38&")",""), IF(Calendario!H38<>"","IVAN("&Calendario!H38&")",""), IF(Calendario!I38<>"","YERAY("&Calendario!I38&")",""))
A6: 5 | B6: 46239 | C6: Mie | D6: =TEXTJOIN(", ";TRUE,IF(Calendario!C39="","RESI",""), IF(Calendario!D39="","OSCAR",""), IF(Calendario!E39="","CLARA",""), IF(Calendario!F39="","ANNA",""), IF(Calendario!G39="","PEPE",""), IF(Calendario!H39="","IVAN",""), IF(Calendario!I39="","YERAY","")) | E6: =TEXTJOIN(", ";TRUE,IF(Calendario!C39<>"","RESI("&Calendario!C39&")",""), IF(Calendario!D39<>"","OSCAR("&Calendario!D39&")",""), IF(Calendario!E39<>"","CLARA("&Calendario!E39&")",""), IF(Calendario!F39<>"","ANNA("&Calendario!F39&")",""), IF(Calendario!G39<>"","PEPE("&Calendario!G39&")",""), IF(Calendario!H39<>"","IVAN("&Calendario!H39&")",""), IF(Calendario!I39<>"","YERAY("&Calendario!I39&")",""))
A7: 6 | B7: 46240 | C7: Jue | D7: =TEXTJOIN(", ";TRUE,IF(Calendario!C40="","RESI",""), IF(Calendario!D40="","OSCAR",""), IF(Calendario!E40="","CLARA",""), IF(Calendario!F40="","ANNA",""), IF(Calendario!G40="","PEPE",""), IF(Calendario!H40="","IVAN",""), IF(Calendario!I40="","YERAY","")) | E7: =TEXTJOIN(", ";TRUE,IF(Calendario!C40<>"","RESI("&Calendario!C40&")",""), IF(Calendario!D40<>"","OSCAR("&Calendario!D40&")",""), IF(Calendario!E40<>"","CLARA("&Calendario!E40&")",""), IF(Calendario!F40<>"","ANNA("&Calendario!F40&")",""), IF(Calendario!G40<>"","PEPE("&Calendario!G40&")",""), IF(Calendario!H40<>"","IVAN("&Calendario!H40&")",""), IF(Calendario!I40<>"","YERAY("&Calendario!I40&")",""))
A8: 7 | B8: 46241 | C8: Vie | D8: =TEXTJOIN(", ";TRUE,IF(Calendario!C41="","RESI",""), IF(Calendario!D41="","OSCAR",""), IF(Calendario!E41="","CLARA",""), IF(Calendario!F41="","ANNA",""), IF(Calendario!G41="","PEPE",""), IF(Calendario!H41="","IVAN",""), IF(Calendario!I41="","YERAY","")) | E8: =TEXTJOIN(", ";TRUE,IF(Calendario!C41<>"","RESI("&Calendario!C41&")",""), IF(Calendario!D41<>"","OSCAR("&Calendario!D41&")",""), IF(Calendario!E41<>"","CLARA("&Calendario!E41&")",""), IF(Calendario!F41<>"","ANNA("&Calendario!F41&")",""), IF(Calendario!G41<>"","PEPE("&Calendario!G41&")",""), IF(Calendario!H41<>"","IVAN("&Calendario!H41&")",""), IF(Calendario!I41<>"","YERAY("&Calendario!I41&")",""))
A9: 8 | B9: 46242 | C9: Sab | D9: =TEXTJOIN(", ";TRUE,IF(Calendario!C42="","RESI",""), IF(Calendario!D42="","OSCAR",""), IF(Calendario!E42="","CLARA",""), IF(Calendario!F42="","ANNA",""), IF(Calendario!G42="","PEPE",""), IF(Calendario!H42="","IVAN",""), IF(Calendario!I42="","YERAY","")) | E9: =TEXTJOIN(", ";TRUE,IF(Calendario!C42<>"","RESI("&Calendario!C42&")",""), IF(Calendario!D42<>"","OSCAR("&Calendario!D42&")",""), IF(Calendario!E42<>"","CLARA("&Calendario!E42&")",""), IF(Calendario!F42<>"","ANNA("&Calendario!F42&")",""), IF(Calendario!G42<>"","PEPE("&Calendario!G42&")",""), IF(Calendario!H42<>"","IVAN("&Calendario!H42&")",""), IF(Calendario!I42<>"","YERAY("&Calendario!I42&")",""))
A10: 9 | B10: 46243 | C10: Dom | D10: =TEXTJOIN(", ";TRUE,IF(Calendario!C43="","RESI",""), IF(Calendario!D43="","OSCAR",""), IF(Calendario!E43="","CLARA",""), IF(Calendario!F43="","ANNA",""), IF(Calendario!G43="","PEPE",""), IF(Calendario!H43="","IVAN",""), IF(Calendario!I43="","YERAY","")) | E10: =TEXTJOIN(", ";TRUE,IF(Calendario!C43<>"","RESI("&Calendario!C43&")",""), IF(Calendario!D43<>"","OSCAR("&Calendario!D43&")",""), IF(Calendario!E43<>"","CLARA("&Calendario!E43&")",""), IF(Calendario!F43<>"","ANNA("&Calendario!F43&")",""), IF(Calendario!G43<>"","PEPE("&Calendario!G43&")",""), IF(Calendario!H43<>"","IVAN("&Calendario!H43&")",""), IF(Calendario!I43<>"","YERAY("&Calendario!I43&")",""))
A11: 10 | B11: 46244 | C11: Lun | D11: =TEXTJOIN(", ";TRUE,IF(Calendario!C44="","RESI",""), IF(Calendario!D44="","OSCAR",""), IF(Calendario!E44="","CLARA",""), IF(Calendario!F44="","ANNA",""), IF(Calendario!G44="","PEPE",""), IF(Calendario!H44="","IVAN",""), IF(Calendario!I44="","YERAY","")) | E11: =TEXTJOIN(", ";TRUE,IF(Calendario!C44<>"","RESI("&Calendario!C44&")",""), IF(Calendario!D44<>"","OSCAR("&Calendario!D44&")",""), IF(Calendario!E44<>"","CLARA("&Calendario!E44&")",""), IF(Calendario!F44<>"","ANNA("&Calendario!F44&")",""), IF(Calendario!G44<>"","PEPE("&Calendario!G44&")",""), IF(Calendario!H44<>"","IVAN("&Calendario!H44&")",""), IF(Calendario!I44<>"","YERAY("&Calendario!I44&")",""))
A12: 11 | B12: 46245 | C12: Mar | D12: =TEXTJOIN(", ";TRUE,IF(Calendario!C45="","RESI",""), IF(Calendario!D45="","OSCAR",""), IF(Calendario!E45="","CLARA",""), IF(Calendario!F45="","ANNA",""), IF(Calendario!G45="","PEPE",""), IF(Calendario!H45="","IVAN",""), IF(Calendario!I45="","YERAY","")) | E12: =TEXTJOIN(", ";TRUE,IF(Calendario!C45<>"","RESI("&Calendario!C45&")",""), IF(Calendario!D45<>"","OSCAR("&Calendario!D45&")",""), IF(Calendario!E45<>"","CLARA("&Calendario!E45&")",""), IF(Calendario!F45<>"","ANNA("&Calendario!F45&")",""), IF(Calendario!G45<>"","PEPE("&Calendario!G45&")",""), IF(Calendario!H45<>"","IVAN("&Calendario!H45&")",""), IF(Calendario!I45<>"","YERAY("&Calendario!I45&")",""))
A13: 12 | B13: 46246 | C13: Mie | D13: =TEXTJOIN(", ";TRUE,IF(Calendario!C46="","RESI",""), IF(Calendario!D46="","OSCAR",""), IF(Calendario!E46="","CLARA",""), IF(Calendario!F46="","ANNA",""), IF(Calendario!G46="","PEPE",""), IF(Calendario!H46="","IVAN",""), IF(Calendario!I46="","YERAY","")) | E13: =TEXTJOIN(", ";TRUE,IF(Calendario!C46<>"","RESI("&Calendario!C46&")",""), IF(Calendario!D46<>"","OSCAR("&Calendario!D46&")",""), IF(Calendario!E46<>"","CLARA("&Calendario!E46&")",""), IF(Calendario!F46<>"","ANNA("&Calendario!F46&")",""), IF(Calendario!G46<>"","PEPE("&Calendario!G46&")",""), IF(Calendario!H46<>"","IVAN("&Calendario!H46&")",""), IF(Calendario!I46<>"","YERAY("&Calendario!I46&")",""))
... A32: 31 | B32: 46265 | C32: Lun | D32: =TEXTJOIN(", ";TRUE,IF(Calendario!C65="","RESI",""), IF(Calendario!D65="","OSCAR",""), IF(Calendario!E65="","CLARA",""), IF(Calendario!F65="","ANNA",""), IF(Calendario!G65="","PEPE",""), IF(Calendario!H65="","IVAN",""), IF(Calendario!I65="","YERAY","")) | E32: =TEXTJOIN(", ";TRUE,IF(Calendario!C65<>"","RESI("&Calendario!C65&")",""), IF(Calendario!D65<>"","OSCAR("&Calendario!D65&")",""), IF(Calendario!E65<>"","CLARA("&Calendario!E65&")",""), IF(Calendario!F65<>"","ANNA("&Calendario!F65&")",""), IF(Calendario!G65<>"","PEPE("&Calendario!G65&")",""), IF(Calendario!H65<>"","IVAN("&Calendario!H65&")",""), IF(Calendario!I65<>"","YERAY("&Calendario!I65&")",""))

Sheet Cuadricula
A1: JULIO 2026
A2: Lun | B2: Mar | C2: Mie | D2: Jue | E2: Vie | F2: Sab | G2: Dom
C3: =TEXTJOIN(CHAR(10);TRUE;TEXT(Calendario!A3,"DD"),IF(Calendario!C3="";"🟢 RESI";""),IF(Calendario!C3="CL";"🟤 RESI(CL)";""),IF(Calendario!C3="FV";"🟡 RESI(FV)";""),IF(Calendario!C3="TM";"🔵 RESI(TM)";""),IF(Calendario!C3="TN";"🟣 RESI(TN)";""),IF(Calendario!C3="TT";"🟠 RESI(TT)";""),IF(Calendario!D3="";"🟢 OSCAR";""),IF(Calendario!D3="CL";"🟤 OSCAR(CL)";""),IF(Calendario!D3="FV";"🟡 OSCAR(FV)";""),IF(Calendario!D3="TM";"🔵 OSCAR(TM)";""),IF(Calendario!D3="TN";"🟣 OSCAR(TN)";""),IF(Calendario!D3="TT";"🟠 OSCAR(TT)";""),IF(Calendario!E3="";"🟢 CLARA";""),IF(Calendario!E3="CL";"🟤 CLARA(CL)";""),IF(Calendario!E3="FV";"🟡 CLARA(FV)";""),IF(Calendario!E3="TM";"🔵 CLARA(TM)";""),IF(Calendario!E3="TN";"🟣 CLARA(TN)";""),IF(Calendario!E3="TT";"🟠 CLARA(TT)";""),IF(Calendario!F3="";"🟢 ANNA";""),IF(Calendario!F3="CL";"🟤 ANNA(CL)";""),IF(Calendario!F3="FV";"🟡 ANNA(FV)";""),IF(Calendario!F3="TM";"🔵 ANNA(TM)";""),IF(Calendario!F3="TN";"🟣 ANNA(TN)";""),IF(Calendario!F3="TT";"🟠 ANNA(TT)";""),IF(Calendario!G3="";"🟢 PEPE";""),IF(Calendario!G3="CL";"🟤 PEPE(CL)";""),IF(Calendario!G3="FV";"🟡 PEPE(FV)";""),IF(Calendario!G3="TM";"🔵 PEPE(TM)";""),IF(Calendario!G3="TN";"🟣 PEPE(TN)";""),IF(Calendario!G3="TT";"🟠 PEPE(TT)";""),IF(Calendario!H3="";"🟢 IVAN";""),IF(Calendario!H3="CL";"🟤 IVAN(CL)";""),IF(Calendario!H3="FV";"🟡 IVAN(FV)";""),IF(Calendario!H3="TM";"🔵 IVAN(TM)";""),IF(Calendario!H3="TN";"🟣 IVAN(TN)";""),IF(Calendario!H3="TT";"🟠 IVAN(TT)";""),IF(Calendario!I3="";"🟢 YERAY";""),IF(Calendario!I3="CL";"🟤 YERAY(CL)";""),IF(Calendario!I3="FV";"🟡 YERAY(FV)";""),IF(Calendario!I3="TM";"🔵 YERAY(TM)";""),IF(Calendario!I3="TN";"🟣 YERAY(TN)";""),IF(Calendario!I3="TT";"🟠 YERAY(TT)";"")) | D3: =TEXTJOIN(CHAR(10);TRUE;TEXT(Calendario!A4,"DD"),IF(Calendario!C4="";"🟢 RESI";""),IF(Calendario!C4="CL";"🟤 RESI(CL)";""),IF(Calendario!C4="FV";"🟡 RESI(FV)";""),IF(Calendario!C4="TM";"🔵 RESI(TM)";""),IF(Calendario!C4="TN";"🟣 RESI(TN)";""),IF(Calendario!C4="TT";"🟠 RESI(TT)";""),IF(Calendario!D4="";"🟢 OSCAR";""),IF(Calendario!D4="CL";"🟤 OSCAR(CL)";""),IF(Calendario!D4="FV";"🟡 OSCAR(FV)";""),IF(Calendario!D4="TM";"🔵 OSCAR(TM)";""),IF(Calendario!D4="TN";"🟣 OSCAR(TN)";""),IF(Calendario!D4="TT";"🟠 OSCAR(TT)";""),IF(Calendario!E4="";"🟢 CLARA";""),IF(Calendario!E4="CL";"🟤 CLARA(CL)";""),IF(Calendario!E4="FV";"🟡 CLARA(FV)";""),IF(Calendario!E4="TM";"🔵 CLARA(TM)";""),IF(Calendario!E4="TN";"🟣 CLARA(TN)";""),IF(Calendario!E4="TT";"🟠 CLARA(TT)";""),IF(Calendario!F4="";"🟢 ANNA";""),IF(Calendario!F4="CL";"🟤 ANNA(CL)";""),IF(Calendario!F4="FV";"🟡 ANNA(FV)";""),IF(Calendario!F4="TM";"🔵 ANNA(TM)";""),IF(Calendario!F4="TN";"🟣 ANNA(TN)";""),IF(Calendario!F4="TT";"🟠 ANNA(TT)";""),IF(Calendario!G4="";"🟢 PEPE";""),IF(Calendario!G4="CL";"🟤 PEPE(CL)";""),IF(Calendario!G4="FV";"🟡 PEPE(FV)";""),IF(Calendario!G4="TM";"🔵 PEPE(TM)";""),IF(Calendario!G4="TN";"🟣 PEPE(TN)";""),IF(Calendario!G4="TT";"🟠 PEPE(TT)";""),IF(Calendario!H4="";"🟢 IVAN";""),IF(Calendario!H4="CL";"🟤 IVAN(CL)";""),IF(Calendario!H4="FV";"🟡 IVAN(FV)";""),IF(Calendario!H4="TM";"🔵 IVAN(TM)";""),IF(Calendario!H4="TN";"🟣 IVAN(TN)";""),IF(Calendario!H4="TT";"🟠 IVAN(TT)";""),IF(Calendario!I4="";"🟢 YERAY";""),IF(Calendario!I4="CL";"🟤 YERAY(CL)";""),IF(Calendario!I4="FV";"🟡 YERAY(FV)";""),IF(Calendario!I4="TM";"🔵 YERAY(TM)";""),IF(Calendario!I4="TN";"🟣 YERAY(TN)";""),IF(Calendario!I4="TT";"🟠 YERAY(TT)";"")) | E3: =TEXTJOIN(CHAR(10);TRUE;TEXT(Calendario!A5,"DD"),IF(Calendario!C5="";"🟢 RESI";""),IF(Calendario!C5="CL";"🟤 RESI(CL)";""),IF(Calendario!C5="FV";"🟡 RESI(FV)";""),IF(Calendario!C5="TM";"🔵 RESI(TM)";""),IF(Calendario!C5="TN";"🟣 RESI(TN)";""),IF(Calendario!C5="TT";"🟠 RESI(TT)";""),IF(Calendario!D5="";"🟢 OSCAR";""),IF(Calendario!D5="CL";"🟤 OSCAR(CL)";""),IF(Calendario!D5="FV";"🟡 OSCAR(FV)";""),IF(Calendario!D5="TM";"🔵 OSCAR(TM)";""),IF(Calendario!D5="TN";"🟣 OSCAR(TN)";""),IF(Calendario!D5="TT";"🟠 OSCAR(TT)";""),IF(Calendario!E5="";"🟢 CLARA";""),IF(Calendario!E5="CL";"🟤 CLARA(CL)";""),IF(Calendario!E5="FV";"🟡 CLARA(FV)";""),IF(Calendario!E5="TM";"🔵 CLARA(TM)";""),IF(Calendario!E5="TN";"🟣 CLARA(TN)";""),IF(Calendario!E5="TT";"🟠 CLARA(TT)";""),IF(Calendario!F5="";"🟢 ANNA";""),IF(Calendario!F5="CL";"🟤 ANNA(CL)";""),IF(Calendario!F5="FV";"🟡 ANNA(FV)";""),IF(Calendario!F5="TM";"🔵 ANNA(TM)";""),IF(Calendario!F5="TN";"🟣 ANNA(TN)";""),IF(Calendario!F5="TT";"🟠 ANNA(TT)";""),IF(Calendario!G5="";"🟢 PEPE";""),IF(Calendario!G5="CL";"🟤 PEPE(CL)";""),IF(Calendario!G5="FV";"🟡 PEPE(FV)";""),IF(Calendario!G5="TM";"🔵 PEPE(TM)";""),IF(Calendario!G5="TN";"🟣 PEPE(TN)";""),IF(Calendario!G5="TT";"🟠 PEPE(TT)";""),IF(Calendario!H5="";"🟢 IVAN";""),IF(Calendario!H5="CL";"🟤 IVAN(CL)";""),IF(Calendario!H5="FV";"🟡 IVAN(FV)";""),IF(Calendario!H5="TM";"🔵 IVAN(TM)";""),IF(Calendario!H5="TN";"🟣 IVAN(TN)";""),IF(Calendario!H5="TT";"🟠 IVAN(TT)";""),IF(Calendario!I5="";"🟢 YERAY";""),IF(Calendario!I5="CL";"🟤 YERAY(CL)";""),IF(Calendario!I5="FV";"🟡 YERAY(FV)";""),IF(Calendario!I5="TM";"🔵 YERAY(TM)";""),IF(Calendario!I5="TN";"🟣 YERAY(TN)";""),IF(Calendario!I5="TT";"🟠 YERAY(TT)";"")) | F3: =TEXTJOIN(CHAR(10);TRUE;TEXT(Calendario!A6,"DD"),IF(Calendario!C6="";"🟢 RESI";""),IF(Calendario!C6="CL";"🟤 RESI(CL)";""),IF(Calendario!C6="FV";"🟡 RESI(FV)";""),IF(Calendario!C6="TM";"🔵 RESI(TM)";""),IF(Calendario!C6="TN";"🟣 RESI(TN)";""),IF(Calendario!C6="TT";"🟠 RESI(TT)";""),IF(Calendario!D6="";"🟢 OSCAR";""),IF(Calendario!D6="CL";"🟤 OSCAR(CL)";""),IF(Calendario!D6="FV";"🟡 OSCAR(FV)";""),IF(Calendario!D6="TM";"🔵 OSCAR(TM)";""),IF(Calendario!D6="TN";"🟣 OSCAR(TN)";""),IF(Calendario!D6="TT";"🟠 OSCAR(TT)";""),IF(Calendario!E6="";"🟢 CLARA";""),IF(Calendario!E6="CL";"🟤 CLARA(CL)";""),IF(Calendario!E6="FV";"🟡 CLARA(FV)";""),IF(Calendario!E6="TM";"🔵 CLARA(TM)";""),IF(Calendario!E6="TN";"🟣 CLARA(TN)";""),IF(Calendario!E6="TT";"🟠 CLARA(TT)";""),IF(Calendario!F6="";"🟢 ANNA";""),IF(Calendario!F6="CL";"🟤 ANNA(CL)";""),IF(Calendario!F6="FV";"🟡 ANNA(FV)";""),IF(Calendario!F6="TM";"🔵 ANNA(TM)";""),IF(Calendario!F6="TN";"🟣 ANNA(TN)";""),IF(Calendario!F6="TT";"🟠 ANNA(TT)";""),IF(Calendario!G6="";"🟢 PEPE";""),IF(Calendario!G6="CL";"🟤 PEPE(CL)";""),IF(Calendario!G6="FV";"🟡 PEPE(FV)";""),IF(Calendario!G6="TM";"🔵 PEPE(TM)";""),IF(Calendario!G6="TN";"🟣 PEPE(TN)";""),IF(Calendario!G6="TT";"🟠 PEPE(TT)";""),IF(Calendario!H6="";"🟢 IVAN";""),IF(Calendario!H6="CL";"🟤 IVAN(CL)";""),IF(Calendario!H6="FV";"🟡 IVAN(FV)";""),IF(Calendario!H6="TM";"🔵 IVAN(TM)";""),IF(Calendario!H6="TN";"🟣 IVAN(TN)";""),IF(Calendario!H6="TT";"🟠 IVAN(TT)";""),IF(Calendario!I6="";"🟢 YERAY";""),IF(Calendario!I6="CL";"🟤 YERAY(CL)";""),IF(Calendario!I6="FV";"🟡 YERAY(FV)";""),IF(Calendario!I6="TM";"🔵 YERAY(TM)";""),IF(Calendario!I6="TN";"🟣 YERAY(TN)";""),IF(Calendario!I6="TT";"🟠 YERAY(TT)";"")) | G3: =TEXTJOIN(CHAR(10);TRUE;TEXT(Calendario!A7,"DD"),IF(Calendario!C7="";"🟢 RESI";""),IF(Calendario!C7="CL";"🟤 RESI(CL)";""),IF(Calendario!C7="FV";"🟡 RESI(FV)";""),IF(Calendario!C7="TM";"🔵 RESI(TM)";""),IF(Calendario!C7="TN";"🟣 RESI(TN)";""),IF(Calendario!C7="TT";"🟠 RESI(TT)";""),IF(Calendario!D7="";"🟢 OSCAR";""),IF(Calendario!D7="CL";"🟤 OSCAR(CL)";""),IF(Calendario!D7="FV";"🟡 OSCAR(FV)";""),IF(Calendario!D7="TM";"🔵 OSCAR(TM)";""),IF(Calendario!D7="TN";"🟣 OSCAR(TN)";""),IF(Calendario!D7="TT";"🟠 OSCAR(TT)";""),IF(Calendario!E7="";"🟢 CLARA";""),IF(Calendario!E7="CL";"🟤 CLARA(CL)";""),IF(Calendario!E7="FV";"🟡 CLARA(FV)";""),IF(Calendario!E7="TM";"🔵 CLARA(TM)";""),IF(Calendario!E7="TN";"🟣 CLARA(TN)";""),IF(Calendario!E7="TT";"🟠 CLARA(TT)";""),IF(Calendario!F7="";"🟢 ANNA";""),IF(Calendario!F7="CL";"🟤 ANNA(CL)";""),IF(Calendario!F7="FV";"🟡 ANNA(FV)";""),IF(Calendario!F7="TM";"🔵 ANNA(TM)";""),IF(Calendario!F7="TN";"🟣 ANNA(TN)";""),IF(Calendario!F7="TT";"🟠 ANNA(TT)";""),IF(Calendario!G7="";"🟢 PEPE";""),IF(Calendario!G7="CL";"🟤 PEPE(CL)";""),IF(Calendario!G7="FV";"🟡 PEPE(FV)";""),IF(Calendario!G7="TM";"🔵 PEPE(TM)";""),IF(Calendario!G7="TN";"🟣 PEPE(TN)";""),IF(Calendario!G7="TT";"🟠 PEPE(TT)";""),IF(Calendario!H7="";"🟢 IVAN";""),IF(Calendario!H7="CL";"🟤 IVAN(CL)";""),IF(Calendario!H7="FV";"🟡 IVAN(FV)";""),IF(Calendario!H7="TM";"🔵 IVAN(TM)";""),IF(Calendario!H7="TN";"🟣 IVAN(TN)";""),IF(Calendario!H7="TT";"🟠 IVAN(TT)";""),IF(Calendario!I7="";"🟢 YERAY";""),IF(Calendario!I7="CL";"🟤 YERAY(CL)";""),IF(Calendario!I7="FV";"🟡 YERAY(FV)";""),IF(Calendario!I7="TM";"🔵 YERAY(TM)";""),IF(Calendario!I7="TN";"🟣 YERAY(TN)";""),IF(Calendario!I7="TT";"🟠 YERAY(TT)";""))
A4: =TEXTJOIN(CHAR(10);TRUE;TEXT(Calendario!A8,"DD"),IF(Calendario!C8="";"🟢 RESI";""),IF(Calendario!C8="CL";"🟤 RESI(CL)";""),IF(Calendario!C8="FV";"🟡 RESI(FV)";""),IF(Calendario!C8="TM";"🔵 RESI(TM)";""),IF(Calendario!C8="TN";"🟣 RESI(TN)";""),IF(Calendario!C8="TT";"🟠 RESI(TT)";""),IF(Calendario!D8="";"🟢 OSCAR";""),IF(Calendario!D8="CL";"🟤 OSCAR(CL)";""),IF(Calendario!D8="FV";"🟡 OSCAR(FV)";""),IF(Calendario!D8="TM";"🔵 OSCAR(TM)";""),IF(Calendario!D8="TN";"🟣 OSCAR(TN)";""),IF(Calendario!D8="TT";"🟠 OSCAR(TT)";""),IF(Calendario!E8="";"🟢 CLARA";""),IF(Calendario!E8="CL";"🟤 CLARA(CL)";""),IF(Calendario!E8="FV";"🟡 CLARA(FV)";""),IF(Calendario!E8="TM";"🔵 CLARA(TM)";""),IF(Calendario!E8="TN";"🟣 CLARA(TN)";""),IF(Calendario!E8="TT";"🟠 CLARA(TT)";""),IF(Calendario!F8="";"🟢 ANNA";""),IF(Calendario!F8="CL";"🟤 ANNA(CL)";""),IF(Calendario!F8="FV";"🟡 ANNA(FV)";""),IF(Calendario!F8="TM";"🔵 ANNA(TM)";""),IF(Calendario!F8="TN";"🟣 ANNA(TN)";""),IF(Calendario!F8="TT";"🟠 ANNA(TT)";""),IF(Calendario!G8="";"🟢 PEPE";""),IF(Calendario!G8="CL";"🟤 PEPE(CL)";""),IF(Calendario!G8="FV";"🟡 PEPE(FV)";""),IF(Calendario!G8="TM";"🔵 PEPE(TM)";""),IF(Calendario!G8="TN";"🟣 PEPE(TN)";""),IF(Calendario!G8="TT";"🟠 PEPE(TT)";""),IF(Calendario!H8="";"🟢 IVAN";""),IF(Calendario!H8="CL";"🟤 IVAN(CL)";""),IF(Calendario!H8="FV";"🟡 IVAN(FV)";""),IF(Calendario!H8="TM";"🔵 IVAN(TM)";""),IF(Calendario!H8="TN";"🟣 IVAN(TN)";""),IF(Calendario!H8="TT";"🟠 IVAN(TT)";""),IF(Calendario!I8="";"🟢 YERAY";""),IF(Calendario!I8="CL";"🟤 YERAY(CL)";""),IF(Calendario!I8="FV";"🟡 YERAY(FV)";""),IF(Calendario!I8="TM";"🔵 YERAY(TM)";""),IF(Calendario!I8="TN";"🟣 YERAY(TN)";""),IF(Calendario!I8="TT";"🟠 YERAY(TT)";"")) | B4: =TEXTJOIN(CHAR(10);TRUE;TEXT(Calendario!A9,"DD"),IF(Calendario!C9="";"🟢 RESI";""),IF(Calendario!C9="CL";"🟤 RESI(CL)";""),IF(Calendario!C9="FV";"🟡 RESI(FV)";""),IF(Calendario!C9="TM";"🔵 RESI(TM)";""),IF(Calendario!C9="TN";"🟣 RESI(TN)";""),IF(Calendario!C9="TT";"🟠 RESI(TT)";""),IF(Calendario!D9="";"🟢 OSCAR";""),IF(Calendario!D9="CL";"🟤 OSCAR(CL)";""),IF(Calendario!D9="FV";"🟡 OSCAR(FV)";""),IF(Calendario!D9="TM";"🔵 OSCAR(TM)";""),IF(Calendario!D9="TN";"🟣 OSCAR(TN)";""),IF(Calendario!D9="TT";"🟠 OSCAR(TT)";""),IF(Calendario!E9="";"🟢 CLARA";""),IF(Calendario!E9="CL";"🟤 CLARA(CL)";""),IF(Calendario!E9="FV";"🟡 CLARA(FV)";""),IF(Calendario!E9="TM";"🔵 CLARA(TM)";""),IF(Calendario!E9="TN";"🟣 CLARA(TN)";""),IF(Calendario!E9="TT";"🟠 CLARA(TT)";""),IF(Calendario!F9="";"🟢 ANNA";""),IF(Calendario!F9="CL";"🟤 ANNA(CL)";""),IF(Calendario!F9="FV";"🟡 ANNA(FV)";""),IF(Calendario!F9="TM";"🔵 ANNA(TM)";""),IF(Calendario!F9="TN";"🟣 ANNA(TN)";""),IF(Calendario!F9="TT";"🟠 ANNA(TT)";""),IF(Calendario!G9="";"🟢 PEPE";""),IF(Calendario!G9="CL";"🟤 PEPE(CL)";""),IF(Calendario!G9="FV";"🟡 PEPE(FV)";""),IF(Calendario!G9="TM";"🔵 PEPE(TM)";""),IF(Calendario!G9="TN";"🟣 PEPE(TN)";""),IF(Calendario!G9="TT";"🟠 PEPE(TT)";""),IF(Calendario!H9="";"🟢 IVAN";""),IF(Calendario!H9="CL";"🟤 IVAN(CL)";""),IF(Calendario!H9="FV";"🟡 IVAN(FV)";""),IF(Calendario!H9="TM";"🔵 IVAN(TM)";""),IF(Calendario!H9="TN";"🟣 IVAN(TN)";""),IF(Calendario!H9="TT";"🟠 IVAN(TT)";""),IF(Calendario!I9="";"🟢 YERAY";""),IF(Calendario!I9="CL";"🟤 YERAY(CL)";""),IF(Calendario!I9="FV";"🟡 YERAY(FV)";""),IF(Calendario!I9="TM";"🔵 YERAY(TM)";""),IF(Calendario!I9="TN";"🟣 YERAY(TN)";""),IF(Calendario!I9="TT";"🟠 YERAY(TT)";"")) | C4: =TEXTJOIN(CHAR(10);TRUE;TEXT(Calendario!A10,"DD"),IF(Calendario!C10="";"🟢 RESI";""),IF(Calendario!C10="CL";"🟤 RESI(CL)";""),IF(Calendario!C10="FV";"🟡 RESI(FV)";""),IF(Calendario!C10="TM";"🔵 RESI(TM)";""),IF(Calendario!C10="TN";"🟣 RESI(TN)";""),IF(Calendario!C10="TT";"🟠 RESI(TT)";""),IF(Calendario!D10="";"🟢 OSCAR";""),IF(Calendario!D10="CL";"🟤 OSCAR(CL)";""),IF(Calendario!D10="FV";"🟡 OSCAR(FV)";""),IF(Calendario!D10="TM";"🔵 OSCAR(TM)";""),IF(Calendario!D10="TN";"🟣 OSCAR(TN)";""),IF(Calendario!D10="TT";"🟠 OSCAR(TT)";""),IF(Calendario!E10="";"🟢 CLARA";""),IF(Calendario!E10="CL";"🟤 CLARA(CL)";""),IF(Calendario!E10="FV";"🟡 CLARA(FV)";""),IF(Calendario!E10="TM";"🔵 CLARA(TM)";""),IF(Calendario!E10="TN";"🟣 CLARA(TN)";""),IF(Calendario!E10="TT";"🟠 CLARA(TT)";""),IF(Calendario!F10="";"🟢 ANNA";""),IF(Calendario!F10="CL";"🟤 ANNA(CL)";""),IF(Calendario!F10="FV";"🟡 ANNA(FV)";""),IF(Calendario!F10="TM";"🔵 ANNA(TM)";""),IF(Calendario!F10="TN";"🟣 ANNA(TN)";""),IF(Calendario!F10="TT";"🟠 ANNA(TT)";""),IF(Calendario!G10="";"🟢 PEPE";""),IF(Calendario!G10="CL";"🟤 PEPE(CL)";""),IF(Calendario!G10="FV";"🟡 PEPE(FV)";""),IF(Calendario!G10="TM";"🔵 PEPE(TM)";""),IF(Calendario!G10="TN";"🟣 PEPE(TN)";""),IF(Calendario!G10="TT";"🟠 PEPE(TT)";""),IF(Calendario!H10="";"🟢 IVAN";""),IF(Calendario!H10="CL";"🟤 IVAN(CL)";""),IF(Calendario!H10="FV";"🟡 IVAN(FV)";""),IF(Calendario!H10="TM";"🔵 IVAN(TM)";""),IF(Calendario!H10="TN";"🟣 IVAN(TN)";""),IF(Calendario!H10="TT";"🟠 IVAN(TT)";""),IF(Calendario!I10="";"🟢 YERAY";""),IF(Calendario!I10="CL";"🟤 YERAY(CL)";""),IF(Calendario!I10="FV";"🟡 YERAY(FV)";""),IF(Calendario!I10="TM";"🔵 YERAY(TM)";""),IF(Calendario!I10="TN";"🟣 YERAY(TN)";""),IF(Calendario!I10="TT";"🟠 YERAY(TT)";"")) | D4: =TEXTJOIN(CHAR(10);TRUE;TEXT(Calendario!A11,"DD"),IF(Calendario!C11="";"🟢 RESI";""),IF(Calendario!C11="CL";"🟤 RESI(CL)";""),IF(Calendario!C11="FV";"🟡 RESI(FV)";""),IF(Calendario!C11="TM";"🔵 RESI(TM)";""),IF(Calendario!C11="TN";"🟣 RESI(TN)";""),IF(Calendario!C11="TT";"🟠 RESI(TT)";""),IF(Calendario!D11="";"🟢 OSCAR";""),IF(Calendario!D11="CL";"🟤 OSCAR(CL)";""),IF(Calendario!D11="FV";"🟡 OSCAR(FV)";""),IF(Calendario!D11="TM";"🔵 OSCAR(TM)";""),IF(Calendario!D11="TN";"🟣 OSCAR(TN)";""),IF(Calendario!D11="TT";"🟠 OSCAR(TT)";""),IF(Calendario!E11="";"🟢 CLARA";""),IF(Calendario!E11="CL";"🟤 CLARA(CL)";""),IF(Calendario!E11="FV";"🟡 CLARA(FV)";""),IF(Calendario!E11="TM";"🔵 CLARA(TM)";""),IF(Calendario!E11="TN";"🟣 CLARA(TN)";""),IF(Calendario!E11="TT";"🟠 CLARA(TT)";""),IF(Calendario!F11="";"🟢 ANNA";""),IF(Calendario!F11="CL";"🟤 ANNA(CL)";""),IF(Calendario!F11="FV";"🟡 ANNA(FV)";""),IF(Calendario!F11="TM";"🔵 ANNA(TM)";""),IF(Calendario!F11="TN";"🟣 ANNA(TN)";""),IF(Calendario!F11="TT";"🟠 ANNA(TT)";""),IF(Calendario!G11="";"🟢 PEPE";""),IF(Calendario!G11="CL";"🟤 PEPE(CL)";""),IF(Calendario!G11="FV";"🟡 PEPE(FV)";""),IF(Calendario!G11="TM";"🔵 PEPE(TM)";""),IF(Calendario!G11="TN";"🟣 PEPE(TN)";""),IF(Calendario!G11="TT";"🟠 PEPE(TT)";""),IF(Calendario!H11="";"🟢 IVAN";""),IF(Calendario!H11="CL";"🟤 IVAN(CL)";""),IF(Calendario!H11="FV";"🟡 IVAN(FV)";""),IF(Calendario!H11="TM";"🔵 IVAN(TM)";""),IF(Calendario!H11="TN";"🟣 IVAN(TN)";""),IF(Calendario!H11="TT";"🟠 IVAN(TT)";""),IF(Calendario!I11="";"🟢 YERAY";""),IF(Calendario!I11="CL";"🟤 YERAY(CL)";""),IF(Calendario!I11="FV";"🟡 YERAY(FV)";""),IF(Calendario!I11="TM";"🔵 YERAY(TM)";""),IF(Calendario!I11="TN";"🟣 YERAY(TN)";""),IF(Calendario!I11="TT";"🟠 YERAY(TT)";"")) | E4: =TEXTJOIN(CHAR(10);TRUE;TEXT(Calendario!A12,"DD"),IF(Calendario!C12="";"🟢 RESI";""),IF(Calendario!C12="CL";"🟤 RESI(CL)";""),IF(Calendario!C12="FV";"🟡 RESI(FV)";""),IF(Calendario!C12="TM";"🔵 RESI(TM)";""),IF(Calendario!C12="TN";"🟣 RESI(TN)";""),IF(Calendario!C12="TT";"🟠 RESI(TT)";""),IF(Calendario!D12="";"🟢 OSCAR";""),IF(Calendario!D12="CL";"🟤 OSCAR(CL)";""),IF(Calendario!D12="FV";"🟡 OSCAR(FV)";""),IF(Calendario!D12="TM";"🔵 OSCAR(TM)";""),IF(Calendario!D12="TN";"🟣 OSCAR(TN)";""),IF(Calendario!D12="TT";"🟠 OSCAR(TT)";""),IF(Calendario!E12="";"🟢 CLARA";""),IF(Calendario!E12="CL";"🟤 CLARA(CL)";""),IF(Calendario!E12="FV";"🟡 CLARA(FV)";""),IF(Calendario!E12="TM";"🔵 CLARA(TM)";""),IF(Calendario!E12="TN";"🟣 CLARA(TN)";""),IF(Calendario!E12="TT";"🟠 CLARA(TT)";""),IF(Calendario!F12="";"🟢 ANNA";""),IF(Calendario!F12="CL";"🟤 ANNA(CL)";""),IF(Calendario!F12="FV";"🟡 ANNA(FV)";""),IF(Calendario!F12="TM";"🔵 ANNA(TM)";""),IF(Calendario!F12="TN";"🟣 ANNA(TN)";""),IF(Calendario!F12="TT";"🟠 ANNA(TT)";""),IF(Calendario!G12="";"🟢 PEPE";""),IF(Calendario!G12="CL";"🟤 PEPE(CL)";""),IF(Calendario!G12="FV";"🟡 PEPE(FV)";""),IF(Calendario!G12="TM";"🔵 PEPE(TM)";""),IF(Calendario!G12="TN";"🟣 PEPE(TN)";""),IF(Calendario!G12="TT";"🟠 PEPE(TT)";""),IF(Calendario!H12="";"🟢 IVAN";""),IF(Calendario!H12="CL";"🟤 IVAN(CL)";""),IF(Calendario!H12="FV";"🟡 IVAN(FV)";""),IF(Calendario!H12="TM";"🔵 IVAN(TM)";""),IF(Calendario!H12="TN";"🟣 IVAN(TN)";""),IF(Calendario!H12="TT";"🟠 IVAN(TT)";""),IF(Calendario!I12="";"🟢 YERAY";""),IF(Calendario!I12="CL";"🟤 YERAY(CL)";""),IF(Calendario!I12="FV";"🟡 YERAY(FV)";""),IF(Calendario!I12="TM";"🔵 YERAY(TM)";""),IF(Calendario!I12="TN";"🟣 YERAY(TN)";""),IF(Calendario!I12="TT";"🟠 YERAY(TT)";"")) | F4: =TEXTJOIN(CHAR(10);TRUE;TEXT(Calendario!A13,"DD"),IF(Calendario!C13="";"🟢 RESI";""),IF(Calendario!C13="CL";"🟤 RESI(CL)";""),IF(Calendario!C13="FV";"🟡 RESI(FV)";""),IF(Calendario!C13="TM";"🔵 RESI(TM)";""),IF(Calendario!C13="TN";"🟣 RESI(TN)";""),IF(Calendario!C13="TT";"🟠 RESI(TT)";""),IF(Calendario!D13="";"🟢 OSCAR";""),IF(Calendario!D13="CL";"🟤 OSCAR(CL)";""),IF(Calendario!D13="FV";"🟡 OSCAR(FV)";""),IF(Calendario!D13="TM";"🔵 OSCAR(TM)";""),IF(Calendario!D13="TN";"🟣 OSCAR(TN)";""),IF(Calendario!D13="TT";"🟠 OSCAR(TT)";""),IF(Calendario!E13="";"🟢 CLARA";""),IF(Calendario!E13="CL";"🟤 CLARA(CL)";""),IF(Calendario!E13="FV";"🟡 CLARA(FV)";""),IF(Calendario!E13="TM";"🔵 CLARA(TM)";""),IF(Calendario!E13="TN";"🟣 CLARA(TN)";""),IF(Calendario!E13="TT";"🟠 CLARA(TT)";""),IF(Calendario!F13="";"🟢 ANNA";""),IF(Calendario!F13="CL";"🟤 ANNA(CL)";""),IF(Calendario!F13="FV";"🟡 ANNA(FV)";""),IF(Calendario!F13="TM";"🔵 ANNA(TM)";""),IF(Calendario!F13="TN";"🟣 ANNA(TN)";""),IF(Calendario!F13="TT";"🟠 ANNA(TT)";""),IF(Calendario!G13="";"🟢 PEPE";""),IF(Calendario!G13="CL";"🟤 PEPE(CL)";""),IF(Calendario!G13="FV";"🟡 PEPE(FV)";""),IF(Calendario!G13="TM";"🔵 PEPE(TM)";""),IF(Calendario!G13="TN";"🟣 PEPE(TN)";""),IF(Calendario!G13="TT";"🟠 PEPE(TT)";""),IF(Calendario!H13="";"🟢 IVAN";""),IF(Calendario!H13="CL";"🟤 IVAN(CL)";""),IF(Calendario!H13="FV";"🟡 IVAN(FV)";""),IF(Calendario!H13="TM";"🔵 IVAN(TM)";""),IF(Calendario!H13="TN";"🟣 IVAN(TN)";""),IF(Calendario!H13="TT";"🟠 IVAN(TT)";""),IF(Calendario!I13="";"🟢 YERAY";""),IF(Calendario!I13="CL";"🟤 YERAY(CL)";""),IF(Calendario!I13="FV";"🟡 YERAY(FV)";""),IF(Calendario!I13="TM";"🔵 YERAY(TM)";""),IF(Calendario!I13="TN";"🟣 YERAY(TN)";""),IF(Calendario!I13="TT";"🟠 YERAY(TT)";"")) | G4: =TEXTJOIN(CHAR(10);TRUE;TEXT(Calendario!A14,"DD"),IF(Calendario!C14="";"🟢 RESI";""),IF(Calendario!C14="CL";"🟤 RESI(CL)";""),IF(Calendario!C14="FV";"🟡 RESI(FV)";""),IF(Calendario!C14="TM";"🔵 RESI(TM)";""),IF(Calendario!C14="TN";"🟣 RESI(TN)";""),IF(Calendario!C14="TT";"🟠 RESI(TT)";""),IF(Calendario!D14="";"🟢 OSCAR";""),IF(Calendario!D14="CL";"🟤 OSCAR(CL)";""),IF(Calendario!D14="FV";"🟡 OSCAR(FV)";""),IF(Calendario!D14="TM";"🔵 OSCAR(TM)";""),IF(Calendario!D14="TN";"🟣 OSCAR(TN)";""),IF(Calendario!D14="TT";"🟠 OSCAR(TT)";""),IF(Calendario!E14="";"🟢 CLARA";""),IF(Calendario!E14="CL";"🟤 CLARA(CL)";""),IF(Calendario!E14="FV";"🟡 CLARA(FV)";""),IF(Calendario!E14="TM";"🔵 CLARA(TM)";""),IF(Calendario!E14="TN";"🟣 CLARA(TN)";""),IF(Calendario!E14="TT";"🟠 CLARA(TT)";""),IF(Calendario!F14="";"🟢 ANNA";""),IF(Calendario!F14="CL";"🟤 ANNA(CL)";""),IF(Calendario!F14="FV";"🟡 ANNA(FV)";""),IF(Calendario!F14="TM";"🔵 ANNA(TM)";""),IF(Calendario!F14="TN";"🟣 ANNA(TN)";""),IF(Calendario!F14="TT";"🟠 ANNA(TT)";""),IF(Calendario!G14="";"🟢 PEPE";""),IF(Calendario!G14="CL";"🟤 PEPE(CL)";""),IF(Calendario!G14="FV";"🟡 PEPE(FV)";""),IF(Calendario!G14="TM";"🔵 PEPE(TM)";""),IF(Calendario!G14="TN";"🟣 PEPE(TN)";""),IF(Calendario!G14="TT";"🟠 PEPE(TT)";""),IF(Calendario!H14="";"🟢 IVAN";""),IF(Calendario!H14="CL";"🟤 IVAN(CL)";""),IF(Calendario!H14="FV";"🟡 IVAN(FV)";""),IF(Calendario!H14="TM";"🔵 IVAN(TM)";""),IF(Calendario!H14="TN";"🟣 IVAN(TN)";""),IF(Calendario!H14="TT";"🟠 IVAN(TT)";""),IF(Calendario!I14="";"🟢 YERAY";""),IF(Calendario!I14="CL";"🟤 YERAY(CL)";""),IF(Calendario!I14="FV";"🟡 YERAY(FV)";""),IF(Calendario!I14="TM";"🔵 YERAY(TM)";""),IF(Calendario!I14="TN";"🟣 YERAY(TN)";""),IF(Calendario!I14="TT";"🟠 YERAY(TT)";""))
